{"text": "2021-02-02T15:34:56.477374+0300 ERROR An error has been caught in function 'contact', process 'MainProcess' (190270), thread 'WorkerThread1' (140295196534528):\nTraceback (most recent call last):\n\n  File \"/opt/python/python-3.7.6/lib/python3.7/threading.py\", line 890, in _bootstrap\n    self._bootstrap_inner()\n    \u2502    \u2514 <function Thread._bootstrap_inner at 0x7f990a2a59e0>\n    \u2514 <WorkerThread(WorkerThread1, started daemon 140295196534528)>\n  File \"/opt/python/python-3.7.6/lib/python3.7/threading.py\", line 926, in _bootstrap_inner\n    self.run()\n    \u2502    \u2514 <function WorkerThread.run at 0x7f99066ea440>\n    \u2514 <WorkerThread(WorkerThread1, started daemon 140295196534528)>\n  File \"/var/www/u0978519/data/pybot/lib/python3.7/site-packages/telebot/util.py\", line 69, in run\n    task(*args, **kwargs)\n    \u2502     \u2502       \u2514 {}\n    \u2502     \u2514 (<telebot.types.Message object at 0x7f99045354d0>,)\n    \u2514 <function message_start.<locals>.handle_query.<locals>.await_text.<locals>.contact at 0x7f99055c0dd0>\n\n> File \"app.py\", line 152, in contact\n    if mailing.send_mail(data=data, text=a):\n       \u2502       \u2502              \u2502          \u2514 '\u0445\u0430\u0447\u0443 \u0447\u0442\u043e\u0442\u043e \u043a\u043b\u0430\u0441\u0441\u043d\u043e\u0435'\n       \u2502       \u2502              \u2514 {'phone': '79161583883', 'user_name': '\u25c7\u0421\u0443\u0449', 'call': '\u041f\u043e\u0434 \u043a\u043b\u044e\u0447 -> \u041c\u043e\u0431\u0438\u043b\u044c\u043d\u043e\u0435 \u043f\u0440\u0438\u043b\u043e\u0436\u0435\u043d\u0438\u0435'}\n       \u2502       \u2514 <function send_mail at 0x7f990560d9e0>\n       \u2514 <module 'services.mailing' from '/var/www/u0978519/data/www/divier.space/telegramDivier/services/mailing.py'>\n\n  File \"/var/www/u0978519/data/www/divier.space/telegramDivier/services/mailing.py\", line 48, in send_mail\n    server.login(sender_email, password)\n    \u2502      \u2502     \u2502             \u2514 'N546823791n'\n    \u2502      \u2502     \u2514 'belinsky.dev@gmail.com'\n    \u2502      \u2514 <function SMTP.login at 0x7f9906438320>\n    \u2514 <smtplib.SMTP_SSL object at 0x7f99055bde50>\n\n  File \"/opt/python/python-3.7.6/lib/python3.7/smtplib.py\", line 730, in login\n    raise last_exception\n          \u2514 SMTPAuthenticationError(534, b'5.7.14 <https://accounts.google.com/signin/continue?sarp=1&scc=1&plt=AKgnsbs\\n5.7.14 1FF07PxDI...\n  File \"/opt/python/python-3.7.6/lib/python3.7/smtplib.py\", line 721, in login\n    initial_response_ok=initial_response_ok)\n                        \u2514 True\n  File \"/opt/python/python-3.7.6/lib/python3.7/smtplib.py\", line 642, in auth\n    raise SMTPAuthenticationError(code, resp)\n          \u2502                       \u2502     \u2514 b'5.7.14 <https://accounts.google.com/signin/continue?sarp=1&scc=1&plt=AKgnsbs\\n5.7.14 1FF07PxDI7AMFgHylIQWiYZmeZ2y4DLjEWPtgI...\n          \u2502                       \u2514 534\n          \u2514 <class 'smtplib.SMTPAuthenticationError'>\n\nsmtplib.SMTPAuthenticationError: (534, b'5.7.14 <https://accounts.google.com/signin/continue?sarp=1&scc=1&plt=AKgnsbs\\n5.7.14 1FF07PxDI7AMFgHylIQWiYZmeZ2y4DLjEWPtgIPRy9ttuwJWiduZzfyAO5EAzHCYQEikk\\n5.7.14 5ePHdQb75nUtxD-_FaCrWNz1GK0oUpKLl14EbUh369sEgggw_AZKl7y6Yf16nkIQ>\\n5.7.14 Please log in via your web browser and then try again.\\n5.7.14  Learn more at\\n5.7.14  https://support.google.com/mail/answer/78754 d23sm3302151lfn.229 - gsmtp')\n", "record": {"elapsed": {"repr": "0:00:35.331376", "seconds": 35.331376}, "exception": {"type": "SMTPAuthenticationError", "value": "(534, b'5.7.14 <https://accounts.google.com/signin/continue?sarp=1&scc=1&plt=AKgnsbs\\n5.7.14 1FF07PxDI7AMFgHylIQWiYZmeZ2y4DLjEWPtgIPRy9ttuwJWiduZzfyAO5EAzHCYQEikk\\n5.7.14 5ePHdQb75nUtxD-_FaCrWNz1GK0oUpKLl14EbUh369sEgggw_AZKl7y6Yf16nkIQ>\\n5.7.14 Please log in via your web browser and then try again.\\n5.7.14  Learn more at\\n5.7.14  https://support.google.com/mail/answer/78754 d23sm3302151lfn.229 - gsmtp')", "traceback": true}, "extra": {}, "file": {"name": "app.py", "path": "app.py"}, "function": "contact", "level": {"icon": "\u274c", "name": "ERROR", "no": 40}, "line": 152, "message": "An error has been caught in function 'contact', process 'MainProcess' (190270), thread 'WorkerThread1' (140295196534528):", "module": "app", "name": "__main__", "process": {"id": 190270, "name": "MainProcess"}, "thread": {"id": 140295196534528, "name": "WorkerThread1"}, "time": {"repr": "2021-02-02 15:34:56.477374+03:00", "timestamp": 1612269296.477374}}}
{"text": "2021-02-02T15:34:56.477374+0300 ERROR An error has been caught in function 'contact', process 'MainProcess' (190270), thread 'WorkerThread1' (140295196534528):\nTraceback (most recent call last):\n\n  File \"/opt/python/python-3.7.6/lib/python3.7/threading.py\", line 890, in _bootstrap\n    self._bootstrap_inner()\n    \u2502    \u2514 <function Thread._bootstrap_inner at 0x7f990a2a59e0>\n    \u2514 <WorkerThread(WorkerThread1, started daemon 140295196534528)>\n  File \"/opt/python/python-3.7.6/lib/python3.7/threading.py\", line 926, in _bootstrap_inner\n    self.run()\n    \u2502    \u2514 <function WorkerThread.run at 0x7f99066ea440>\n    \u2514 <WorkerThread(WorkerThread1, started daemon 140295196534528)>\n  File \"/var/www/u0978519/data/pybot/lib/python3.7/site-packages/telebot/util.py\", line 69, in run\n    task(*args, **kwargs)\n    \u2502     \u2502       \u2514 {}\n    \u2502     \u2514 (<telebot.types.Message object at 0x7f99045354d0>,)\n    \u2514 <function message_start.<locals>.handle_query.<locals>.await_text.<locals>.contact at 0x7f99055c0dd0>\n\n> File \"app.py\", line 152, in contact\n    if mailing.send_mail(data=data, text=a):\n       \u2502       \u2502              \u2502          \u2514 '\u0445\u0430\u0447\u0443 \u0447\u0442\u043e\u0442\u043e \u043a\u043b\u0430\u0441\u0441\u043d\u043e\u0435'\n       \u2502       \u2502              \u2514 {'phone': '79161583883', 'user_name': '\u25c7\u0421\u0443\u0449', 'call': '\u041f\u043e\u0434 \u043a\u043b\u044e\u0447 -> \u041c\u043e\u0431\u0438\u043b\u044c\u043d\u043e\u0435 \u043f\u0440\u0438\u043b\u043e\u0436\u0435\u043d\u0438\u0435'}\n       \u2502       \u2514 <function send_mail at 0x7f990560d9e0>\n       \u2514 <module 'services.mailing' from '/var/www/u0978519/data/www/divier.space/telegramDivier/services/mailing.py'>\n\n  File \"/var/www/u0978519/data/www/divier.space/telegramDivier/services/mailing.py\", line 48, in send_mail\n    server.login(sender_email, password)\n    \u2502      \u2502     \u2502             \u2514 'N546823791n'\n    \u2502      \u2502     \u2514 'belinsky.dev@gmail.com'\n    \u2502      \u2514 <function SMTP.login at 0x7f9906438320>\n    \u2514 <smtplib.SMTP_SSL object at 0x7f99055bde50>\n\n  File \"/opt/python/python-3.7.6/lib/python3.7/smtplib.py\", line 730, in login\n    raise last_exception\n          \u2514 SMTPAuthenticationError(534, b'5.7.14 <https://accounts.google.com/signin/continue?sarp=1&scc=1&plt=AKgnsbs\\n5.7.14 1FF07PxDI...\n  File \"/opt/python/python-3.7.6/lib/python3.7/smtplib.py\", line 721, in login\n    initial_response_ok=initial_response_ok)\n                        \u2514 True\n  File \"/opt/python/python-3.7.6/lib/python3.7/smtplib.py\", line 642, in auth\n    raise SMTPAuthenticationError(code, resp)\n          \u2502                       \u2502     \u2514 b'5.7.14 <https://accounts.google.com/signin/continue?sarp=1&scc=1&plt=AKgnsbs\\n5.7.14 1FF07PxDI7AMFgHylIQWiYZmeZ2y4DLjEWPtgI...\n          \u2502                       \u2514 534\n          \u2514 <class 'smtplib.SMTPAuthenticationError'>\n\nsmtplib.SMTPAuthenticationError: (534, b'5.7.14 <https://accounts.google.com/signin/continue?sarp=1&scc=1&plt=AKgnsbs\\n5.7.14 1FF07PxDI7AMFgHylIQWiYZmeZ2y4DLjEWPtgIPRy9ttuwJWiduZzfyAO5EAzHCYQEikk\\n5.7.14 5ePHdQb75nUtxD-_FaCrWNz1GK0oUpKLl14EbUh369sEgggw_AZKl7y6Yf16nkIQ>\\n5.7.14 Please log in via your web browser and then try again.\\n5.7.14  Learn more at\\n5.7.14  https://support.google.com/mail/answer/78754 d23sm3302151lfn.229 - gsmtp')\n", "record": {"elapsed": {"repr": "0:00:35.331376", "seconds": 35.331376}, "exception": {"type": "SMTPAuthenticationError", "value": "(534, b'5.7.14 <https://accounts.google.com/signin/continue?sarp=1&scc=1&plt=AKgnsbs\\n5.7.14 1FF07PxDI7AMFgHylIQWiYZmeZ2y4DLjEWPtgIPRy9ttuwJWiduZzfyAO5EAzHCYQEikk\\n5.7.14 5ePHdQb75nUtxD-_FaCrWNz1GK0oUpKLl14EbUh369sEgggw_AZKl7y6Yf16nkIQ>\\n5.7.14 Please log in via your web browser and then try again.\\n5.7.14  Learn more at\\n5.7.14  https://support.google.com/mail/answer/78754 d23sm3302151lfn.229 - gsmtp')", "traceback": true}, "extra": {}, "file": {"name": "app.py", "path": "app.py"}, "function": "contact", "level": {"icon": "\u274c", "name": "ERROR", "no": 40}, "line": 152, "message": "An error has been caught in function 'contact', process 'MainProcess' (190270), thread 'WorkerThread1' (140295196534528):", "module": "app", "name": "__main__", "process": {"id": 190270, "name": "MainProcess"}, "thread": {"id": 140295196534528, "name": "WorkerThread1"}, "time": {"repr": "2021-02-02 15:34:56.477374+03:00", "timestamp": 1612269296.477374}}}
{"text": "2021-02-02T15:48:05.424355+0300 ERROR An error has been caught in function 'contact', process 'MainProcess' (60012), thread 'WorkerThread1' (140325181925120):\nTraceback (most recent call last):\n\n  File \"/opt/python/python-3.7.6/lib/python3.7/threading.py\", line 890, in _bootstrap\n    self._bootstrap_inner()\n    \u2502    \u2514 <function Thread._bootstrap_inner at 0x7fa005695950>\n    \u2514 <WorkerThread(WorkerThread1, started daemon 140325181925120)>\n  File \"/opt/python/python-3.7.6/lib/python3.7/threading.py\", line 926, in _bootstrap_inner\n    self.run()\n    \u2502    \u2514 <function WorkerThread.run at 0x7fa001b410e0>\n    \u2514 <WorkerThread(WorkerThread1, started daemon 140325181925120)>\n  File \"/var/www/u0978519/data/pybot/lib/python3.7/site-packages/telebot/util.py\", line 69, in run\n    task(*args, **kwargs)\n    \u2502     \u2502       \u2514 {}\n    \u2502     \u2514 (<telebot.types.Message object at 0x7fa00018fe10>,)\n    \u2514 <function message_start.<locals>.handle_query.<locals>.contact at 0x7fa00018c170>\n\n> File \"app.py\", line 64, in contact\n    if mailing.send_mail(data=data):\n       \u2502       \u2502              \u2514 {'phone': '79161583883', 'user_name': '\u25c7\u0421\u0443\u0449', 'call': '\u0424\u043e\u0440\u043c\u0430 \u0438\u0437 \u0441\u0442\u0430\u0440\u0442\u043e\u0432\u043e\u0433\u043e \u043c\u0435\u043d\u044e'}\n       \u2502       \u2514 <function send_mail at 0x7fa000a68680>\n       \u2514 <module 'services.mailing' from '/var/www/u0978519/data/www/divier.space/telegramDivier/services/mailing.py'>\n\n  File \"/var/www/u0978519/data/www/divier.space/telegramDivier/services/mailing.py\", line 48, in send_mail\n    server.login(sender_email, password)\n    \u2502      \u2502     \u2502             \u2514 'N546823791n'\n    \u2502      \u2502     \u2514 'belinsky.dev@gmail.com'\n    \u2502      \u2514 <function SMTP.login at 0x7fa00188ef80>\n    \u2514 <smtplib.SMTP_SSL object at 0x7fa00560bf90>\n\n  File \"/opt/python/python-3.7.6/lib/python3.7/smtplib.py\", line 730, in login\n    raise last_exception\n          \u2514 SMTPAuthenticationError(534, b'5.7.14 <https://accounts.google.com/signin/continue?sarp=1&scc=1&plt=AKgnsbt\\n5.7.14 KvS9Xe2zS...\n  File \"/opt/python/python-3.7.6/lib/python3.7/smtplib.py\", line 721, in login\n    initial_response_ok=initial_response_ok)\n                        \u2514 True\n  File \"/opt/python/python-3.7.6/lib/python3.7/smtplib.py\", line 642, in auth\n    raise SMTPAuthenticationError(code, resp)\n          \u2502                       \u2502     \u2514 b'5.7.14 <https://accounts.google.com/signin/continue?sarp=1&scc=1&plt=AKgnsbt\\n5.7.14 KvS9Xe2zSYo44KvMT7ejyTZ2w_TViSc6p7J0OF...\n          \u2502                       \u2514 534\n          \u2514 <class 'smtplib.SMTPAuthenticationError'>\n\nsmtplib.SMTPAuthenticationError: (534, b'5.7.14 <https://accounts.google.com/signin/continue?sarp=1&scc=1&plt=AKgnsbt\\n5.7.14 KvS9Xe2zSYo44KvMT7ejyTZ2w_TViSc6p7J0OFhCeFMuBdB-cy6Gt_rcTajydgppMvLRv\\n5.7.14 nWfBAHydBoV6GlXLjeKmt1IeU-U-rrKRpA5AzkWzGF-qeYdCrwklqBOtu4nB-9x5>\\n5.7.14 Please log in via your web browser and then try again.\\n5.7.14  Learn more at\\n5.7.14  https://support.google.com/mail/answer/78754 c17sm3298265lfs.217 - gsmtp')\n", "record": {"elapsed": {"repr": "0:00:19.572905", "seconds": 19.572905}, "exception": {"type": "SMTPAuthenticationError", "value": "(534, b'5.7.14 <https://accounts.google.com/signin/continue?sarp=1&scc=1&plt=AKgnsbt\\n5.7.14 KvS9Xe2zSYo44KvMT7ejyTZ2w_TViSc6p7J0OFhCeFMuBdB-cy6Gt_rcTajydgppMvLRv\\n5.7.14 nWfBAHydBoV6GlXLjeKmt1IeU-U-rrKRpA5AzkWzGF-qeYdCrwklqBOtu4nB-9x5>\\n5.7.14 Please log in via your web browser and then try again.\\n5.7.14  Learn more at\\n5.7.14  https://support.google.com/mail/answer/78754 c17sm3298265lfs.217 - gsmtp')", "traceback": true}, "extra": {}, "file": {"name": "app.py", "path": "app.py"}, "function": "contact", "level": {"icon": "\u274c", "name": "ERROR", "no": 40}, "line": 64, "message": "An error has been caught in function 'contact', process 'MainProcess' (60012), thread 'WorkerThread1' (140325181925120):", "module": "app", "name": "__main__", "process": {"id": 60012, "name": "MainProcess"}, "thread": {"id": 140325181925120, "name": "WorkerThread1"}, "time": {"repr": "2021-02-02 15:48:05.424355+03:00", "timestamp": 1612270085.424355}}}
{"text": "2021-02-02T15:48:05.424355+0300 ERROR An error has been caught in function 'contact', process 'MainProcess' (60012), thread 'WorkerThread1' (140325181925120):\nTraceback (most recent call last):\n\n  File \"/opt/python/python-3.7.6/lib/python3.7/threading.py\", line 890, in _bootstrap\n    self._bootstrap_inner()\n    \u2502    \u2514 <function Thread._bootstrap_inner at 0x7fa005695950>\n    \u2514 <WorkerThread(WorkerThread1, started daemon 140325181925120)>\n  File \"/opt/python/python-3.7.6/lib/python3.7/threading.py\", line 926, in _bootstrap_inner\n    self.run()\n    \u2502    \u2514 <function WorkerThread.run at 0x7fa001b410e0>\n    \u2514 <WorkerThread(WorkerThread1, started daemon 140325181925120)>\n  File \"/var/www/u0978519/data/pybot/lib/python3.7/site-packages/telebot/util.py\", line 69, in run\n    task(*args, **kwargs)\n    \u2502     \u2502       \u2514 {}\n    \u2502     \u2514 (<telebot.types.Message object at 0x7fa00018fe10>,)\n    \u2514 <function message_start.<locals>.handle_query.<locals>.contact at 0x7fa00018c170>\n\n> File \"app.py\", line 64, in contact\n    if mailing.send_mail(data=data):\n       \u2502       \u2502              \u2514 {'phone': '79161583883', 'user_name': '\u25c7\u0421\u0443\u0449', 'call': '\u0424\u043e\u0440\u043c\u0430 \u0438\u0437 \u0441\u0442\u0430\u0440\u0442\u043e\u0432\u043e\u0433\u043e \u043c\u0435\u043d\u044e'}\n       \u2502       \u2514 <function send_mail at 0x7fa000a68680>\n       \u2514 <module 'services.mailing' from '/var/www/u0978519/data/www/divier.space/telegramDivier/services/mailing.py'>\n\n  File \"/var/www/u0978519/data/www/divier.space/telegramDivier/services/mailing.py\", line 48, in send_mail\n    server.login(sender_email, password)\n    \u2502      \u2502     \u2502             \u2514 'N546823791n'\n    \u2502      \u2502     \u2514 'belinsky.dev@gmail.com'\n    \u2502      \u2514 <function SMTP.login at 0x7fa00188ef80>\n    \u2514 <smtplib.SMTP_SSL object at 0x7fa00560bf90>\n\n  File \"/opt/python/python-3.7.6/lib/python3.7/smtplib.py\", line 730, in login\n    raise last_exception\n          \u2514 SMTPAuthenticationError(534, b'5.7.14 <https://accounts.google.com/signin/continue?sarp=1&scc=1&plt=AKgnsbt\\n5.7.14 KvS9Xe2zS...\n  File \"/opt/python/python-3.7.6/lib/python3.7/smtplib.py\", line 721, in login\n    initial_response_ok=initial_response_ok)\n                        \u2514 True\n  File \"/opt/python/python-3.7.6/lib/python3.7/smtplib.py\", line 642, in auth\n    raise SMTPAuthenticationError(code, resp)\n          \u2502                       \u2502     \u2514 b'5.7.14 <https://accounts.google.com/signin/continue?sarp=1&scc=1&plt=AKgnsbt\\n5.7.14 KvS9Xe2zSYo44KvMT7ejyTZ2w_TViSc6p7J0OF...\n          \u2502                       \u2514 534\n          \u2514 <class 'smtplib.SMTPAuthenticationError'>\n\nsmtplib.SMTPAuthenticationError: (534, b'5.7.14 <https://accounts.google.com/signin/continue?sarp=1&scc=1&plt=AKgnsbt\\n5.7.14 KvS9Xe2zSYo44KvMT7ejyTZ2w_TViSc6p7J0OFhCeFMuBdB-cy6Gt_rcTajydgppMvLRv\\n5.7.14 nWfBAHydBoV6GlXLjeKmt1IeU-U-rrKRpA5AzkWzGF-qeYdCrwklqBOtu4nB-9x5>\\n5.7.14 Please log in via your web browser and then try again.\\n5.7.14  Learn more at\\n5.7.14  https://support.google.com/mail/answer/78754 c17sm3298265lfs.217 - gsmtp')\n", "record": {"elapsed": {"repr": "0:00:19.572905", "seconds": 19.572905}, "exception": {"type": "SMTPAuthenticationError", "value": "(534, b'5.7.14 <https://accounts.google.com/signin/continue?sarp=1&scc=1&plt=AKgnsbt\\n5.7.14 KvS9Xe2zSYo44KvMT7ejyTZ2w_TViSc6p7J0OFhCeFMuBdB-cy6Gt_rcTajydgppMvLRv\\n5.7.14 nWfBAHydBoV6GlXLjeKmt1IeU-U-rrKRpA5AzkWzGF-qeYdCrwklqBOtu4nB-9x5>\\n5.7.14 Please log in via your web browser and then try again.\\n5.7.14  Learn more at\\n5.7.14  https://support.google.com/mail/answer/78754 c17sm3298265lfs.217 - gsmtp')", "traceback": true}, "extra": {}, "file": {"name": "app.py", "path": "app.py"}, "function": "contact", "level": {"icon": "\u274c", "name": "ERROR", "no": 40}, "line": 64, "message": "An error has been caught in function 'contact', process 'MainProcess' (60012), thread 'WorkerThread1' (140325181925120):", "module": "app", "name": "__main__", "process": {"id": 60012, "name": "MainProcess"}, "thread": {"id": 140325181925120, "name": "WorkerThread1"}, "time": {"repr": "2021-02-02 15:48:05.424355+03:00", "timestamp": 1612270085.424355}}}
{"text": "2021-02-02T15:50:09.040627+0300 ERROR An error has been caught in function 'contact', process 'MainProcess' (109336), thread 'WorkerThread2' (139813929658112):\nTraceback (most recent call last):\n\n  File \"/opt/python/python-3.7.6/lib/python3.7/threading.py\", line 890, in _bootstrap\n    self._bootstrap_inner()\n    \u2502    \u2514 <function Thread._bootstrap_inner at 0x7f28fceae950>\n    \u2514 <WorkerThread(WorkerThread2, started daemon 139813929658112)>\n  File \"/opt/python/python-3.7.6/lib/python3.7/threading.py\", line 926, in _bootstrap_inner\n    self.run()\n    \u2502    \u2514 <function WorkerThread.run at 0x7f28f931c0e0>\n    \u2514 <WorkerThread(WorkerThread2, started daemon 139813929658112)>\n  File \"/var/www/u0978519/data/pybot/lib/python3.7/site-packages/telebot/util.py\", line 69, in run\n    task(*args, **kwargs)\n    \u2502     \u2502       \u2514 {}\n    \u2502     \u2514 (<telebot.types.Message object at 0x7f28f6164410>,)\n    \u2514 <function message_start.<locals>.handle_query.<locals>.contact at 0x7f28f8242b00>\n\n> File \"app.py\", line 65, in contact\n    if mailing.send_mail(data=data):\n       \u2502       \u2502              \u2514 {'phone': '79161583883', 'user_name': '\u25c7\u0421\u0443\u0449', 'call': '\u0424\u043e\u0440\u043c\u0430 \u0438\u0437 \u0441\u0442\u0430\u0440\u0442\u043e\u0432\u043e\u0433\u043e \u043c\u0435\u043d\u044e'}\n       \u2502       \u2514 <function send_mail at 0x7f28f8242680>\n       \u2514 <module 'services.mailing' from '/var/www/u0978519/data/www/divier.space/telegramDivier/services/mailing.py'>\n\n  File \"/var/www/u0978519/data/www/divier.space/telegramDivier/services/mailing.py\", line 48, in send_mail\n    server.login(sender_email, password)\n    \u2502      \u2502     \u2502             \u2514 'N546823791n'\n    \u2502      \u2502     \u2514 'belinsky.dev@gmail.com'\n    \u2502      \u2514 <function SMTP.login at 0x7f28f9067f80>\n    \u2514 <smtplib.SMTP_SSL object at 0x7f28f616b910>\n\n  File \"/opt/python/python-3.7.6/lib/python3.7/smtplib.py\", line 730, in login\n    raise last_exception\n          \u2514 SMTPAuthenticationError(534, b'5.7.14 <https://accounts.google.com/signin/continue?sarp=1&scc=1&plt=AKgnsbt\\n5.7.14 a987VaSM1...\n  File \"/opt/python/python-3.7.6/lib/python3.7/smtplib.py\", line 721, in login\n    initial_response_ok=initial_response_ok)\n                        \u2514 True\n  File \"/opt/python/python-3.7.6/lib/python3.7/smtplib.py\", line 642, in auth\n    raise SMTPAuthenticationError(code, resp)\n          \u2502                       \u2502     \u2514 b'5.7.14 <https://accounts.google.com/signin/continue?sarp=1&scc=1&plt=AKgnsbt\\n5.7.14 a987VaSM1AiTfe0mBmLJPJqcMMnfKu2OYTck3N...\n          \u2502                       \u2514 534\n          \u2514 <class 'smtplib.SMTPAuthenticationError'>\n\nsmtplib.SMTPAuthenticationError: (534, b'5.7.14 <https://accounts.google.com/signin/continue?sarp=1&scc=1&plt=AKgnsbt\\n5.7.14 a987VaSM1AiTfe0mBmLJPJqcMMnfKu2OYTck3NwqQK6WM1P1LjjPvdgYqBS1dwk1UYe9w\\n5.7.14 M4DJVoc-CMe_y4bV3xmre6_4zCBZA7f1Xm8dCklRriyAiNlDXy2buqIgCBBZ5Vj4>\\n5.7.14 Please log in via your web browser and then try again.\\n5.7.14  Learn more at\\n5.7.14  https://support.google.com/mail/answer/78754 n7sm3296756lfu.123 - gsmtp')\n", "record": {"elapsed": {"repr": "0:00:12.002335", "seconds": 12.002335}, "exception": {"type": "SMTPAuthenticationError", "value": "(534, b'5.7.14 <https://accounts.google.com/signin/continue?sarp=1&scc=1&plt=AKgnsbt\\n5.7.14 a987VaSM1AiTfe0mBmLJPJqcMMnfKu2OYTck3NwqQK6WM1P1LjjPvdgYqBS1dwk1UYe9w\\n5.7.14 M4DJVoc-CMe_y4bV3xmre6_4zCBZA7f1Xm8dCklRriyAiNlDXy2buqIgCBBZ5Vj4>\\n5.7.14 Please log in via your web browser and then try again.\\n5.7.14  Learn more at\\n5.7.14  https://support.google.com/mail/answer/78754 n7sm3296756lfu.123 - gsmtp')", "traceback": true}, "extra": {}, "file": {"name": "app.py", "path": "app.py"}, "function": "contact", "level": {"icon": "\u274c", "name": "ERROR", "no": 40}, "line": 65, "message": "An error has been caught in function 'contact', process 'MainProcess' (109336), thread 'WorkerThread2' (139813929658112):", "module": "app", "name": "__main__", "process": {"id": 109336, "name": "MainProcess"}, "thread": {"id": 139813929658112, "name": "WorkerThread2"}, "time": {"repr": "2021-02-02 15:50:09.040627+03:00", "timestamp": 1612270209.040627}}}
{"text": "2021-02-02T15:50:09.040627+0300 ERROR An error has been caught in function 'contact', process 'MainProcess' (109336), thread 'WorkerThread2' (139813929658112):\nTraceback (most recent call last):\n\n  File \"/opt/python/python-3.7.6/lib/python3.7/threading.py\", line 890, in _bootstrap\n    self._bootstrap_inner()\n    \u2502    \u2514 <function Thread._bootstrap_inner at 0x7f28fceae950>\n    \u2514 <WorkerThread(WorkerThread2, started daemon 139813929658112)>\n  File \"/opt/python/python-3.7.6/lib/python3.7/threading.py\", line 926, in _bootstrap_inner\n    self.run()\n    \u2502    \u2514 <function WorkerThread.run at 0x7f28f931c0e0>\n    \u2514 <WorkerThread(WorkerThread2, started daemon 139813929658112)>\n  File \"/var/www/u0978519/data/pybot/lib/python3.7/site-packages/telebot/util.py\", line 69, in run\n    task(*args, **kwargs)\n    \u2502     \u2502       \u2514 {}\n    \u2502     \u2514 (<telebot.types.Message object at 0x7f28f6164410>,)\n    \u2514 <function message_start.<locals>.handle_query.<locals>.contact at 0x7f28f8242b00>\n\n> File \"app.py\", line 65, in contact\n    if mailing.send_mail(data=data):\n       \u2502       \u2502              \u2514 {'phone': '79161583883', 'user_name': '\u25c7\u0421\u0443\u0449', 'call': '\u0424\u043e\u0440\u043c\u0430 \u0438\u0437 \u0441\u0442\u0430\u0440\u0442\u043e\u0432\u043e\u0433\u043e \u043c\u0435\u043d\u044e'}\n       \u2502       \u2514 <function send_mail at 0x7f28f8242680>\n       \u2514 <module 'services.mailing' from '/var/www/u0978519/data/www/divier.space/telegramDivier/services/mailing.py'>\n\n  File \"/var/www/u0978519/data/www/divier.space/telegramDivier/services/mailing.py\", line 48, in send_mail\n    server.login(sender_email, password)\n    \u2502      \u2502     \u2502             \u2514 'N546823791n'\n    \u2502      \u2502     \u2514 'belinsky.dev@gmail.com'\n    \u2502      \u2514 <function SMTP.login at 0x7f28f9067f80>\n    \u2514 <smtplib.SMTP_SSL object at 0x7f28f616b910>\n\n  File \"/opt/python/python-3.7.6/lib/python3.7/smtplib.py\", line 730, in login\n    raise last_exception\n          \u2514 SMTPAuthenticationError(534, b'5.7.14 <https://accounts.google.com/signin/continue?sarp=1&scc=1&plt=AKgnsbt\\n5.7.14 a987VaSM1...\n  File \"/opt/python/python-3.7.6/lib/python3.7/smtplib.py\", line 721, in login\n    initial_response_ok=initial_response_ok)\n                        \u2514 True\n  File \"/opt/python/python-3.7.6/lib/python3.7/smtplib.py\", line 642, in auth\n    raise SMTPAuthenticationError(code, resp)\n          \u2502                       \u2502     \u2514 b'5.7.14 <https://accounts.google.com/signin/continue?sarp=1&scc=1&plt=AKgnsbt\\n5.7.14 a987VaSM1AiTfe0mBmLJPJqcMMnfKu2OYTck3N...\n          \u2502                       \u2514 534\n          \u2514 <class 'smtplib.SMTPAuthenticationError'>\n\nsmtplib.SMTPAuthenticationError: (534, b'5.7.14 <https://accounts.google.com/signin/continue?sarp=1&scc=1&plt=AKgnsbt\\n5.7.14 a987VaSM1AiTfe0mBmLJPJqcMMnfKu2OYTck3NwqQK6WM1P1LjjPvdgYqBS1dwk1UYe9w\\n5.7.14 M4DJVoc-CMe_y4bV3xmre6_4zCBZA7f1Xm8dCklRriyAiNlDXy2buqIgCBBZ5Vj4>\\n5.7.14 Please log in via your web browser and then try again.\\n5.7.14  Learn more at\\n5.7.14  https://support.google.com/mail/answer/78754 n7sm3296756lfu.123 - gsmtp')\n", "record": {"elapsed": {"repr": "0:00:12.002335", "seconds": 12.002335}, "exception": {"type": "SMTPAuthenticationError", "value": "(534, b'5.7.14 <https://accounts.google.com/signin/continue?sarp=1&scc=1&plt=AKgnsbt\\n5.7.14 a987VaSM1AiTfe0mBmLJPJqcMMnfKu2OYTck3NwqQK6WM1P1LjjPvdgYqBS1dwk1UYe9w\\n5.7.14 M4DJVoc-CMe_y4bV3xmre6_4zCBZA7f1Xm8dCklRriyAiNlDXy2buqIgCBBZ5Vj4>\\n5.7.14 Please log in via your web browser and then try again.\\n5.7.14  Learn more at\\n5.7.14  https://support.google.com/mail/answer/78754 n7sm3296756lfu.123 - gsmtp')", "traceback": true}, "extra": {}, "file": {"name": "app.py", "path": "app.py"}, "function": "contact", "level": {"icon": "\u274c", "name": "ERROR", "no": 40}, "line": 65, "message": "An error has been caught in function 'contact', process 'MainProcess' (109336), thread 'WorkerThread2' (139813929658112):", "module": "app", "name": "__main__", "process": {"id": 109336, "name": "MainProcess"}, "thread": {"id": 139813929658112, "name": "WorkerThread2"}, "time": {"repr": "2021-02-02 15:50:09.040627+03:00", "timestamp": 1612270209.040627}}}
{"text": "2021-02-02T15:56:46.388760+0300 ERROR An error has been caught in function 'contact', process 'MainProcess' (4940), thread 'WorkerThread2' (308):\nTraceback (most recent call last):\n\n  File \"C:\\Users\\AV\\AppData\\Local\\Programs\\Python\\Python37\\lib\\threading.py\", line 890, in _bootstrap\n    self._bootstrap_inner()\n    |    -> <function Thread._bootstrap_inner at 0x0000012BFFDF1558>\n    -> <WorkerThread(WorkerThread2, started daemon 308)>\n\n  File \"C:\\Users\\AV\\AppData\\Local\\Programs\\Python\\Python37\\lib\\threading.py\", line 926, in _bootstrap_inner\n    self.run()\n    |    -> <function WorkerThread.run at 0x0000012B81E29D38>\n    -> <WorkerThread(WorkerThread2, started daemon 308)>\n\n  File \"D:\\nikita\\tgbot\\venv\\lib\\site-packages\\telebot\\util.py\", line 69, in run\n    task(*args, **kwargs)\n    |     |       -> {}\n    |     -> (<telebot.types.Message object at 0x0000012B8205C988>,)\n    -> <function message_start.<locals>.handle_query.<locals>.contact at 0x0000012B8213A8B8>\n\n> File \"D:/nikita/tgbot/app.py\", line 65, in contact\n    if mailing.send_mail(data=data):\n       |       |              -> {'phone': '79161583883', 'user_name': '\u25c7\u0421\u0443\u0449', 'call': '\u0424\u043e\u0440\u043c\u0430 \u0438\u0437 \u0441\u0442\u0430\u0440\u0442\u043e\u0432\u043e\u0433\u043e \u043c\u0435\u043d\u044e'}\n       |       -> <function send_mail at 0x0000012B820EF318>\n       -> <module 'services.mailing' from 'D:\\\\nikita\\\\tgbot\\\\services\\\\mailing.py'>\n\n  File \"D:\\nikita\\tgbot\\services\\mailing.py\", line 48, in send_mail\n    server.login(sender_email, password)\n    |      |     |             -> 'N546823791'\n    |      |     -> 'belinsky.dev@gmail.com'\n    |      -> <function SMTP.login at 0x0000012B81E9A168>\n    -> <smtplib.SMTP_SSL object at 0x0000012B82170388>\n\n  File \"C:\\Users\\AV\\AppData\\Local\\Programs\\Python\\Python37\\lib\\smtplib.py\", line 730, in login\n    raise last_exception\n          -> SMTPAuthenticationError(535, b'5.7.8 Username and Password not accepted. Learn more at\\n5.7.8  https://support.google.com/mai...\n\n  File \"C:\\Users\\AV\\AppData\\Local\\Programs\\Python\\Python37\\lib\\smtplib.py\", line 721, in login\n    initial_response_ok=initial_response_ok)\n                        -> True\n\n  File \"C:\\Users\\AV\\AppData\\Local\\Programs\\Python\\Python37\\lib\\smtplib.py\", line 642, in auth\n    raise SMTPAuthenticationError(code, resp)\n          |                       |     -> b'5.7.8 Username and Password not accepted. Learn more at\\n5.7.8  https://support.google.com/mail/?p=BadCredentials f20sm3302...\n          |                       -> 535\n          -> <class 'smtplib.SMTPAuthenticationError'>\n\nsmtplib.SMTPAuthenticationError: (535, b'5.7.8 Username and Password not accepted. Learn more at\\n5.7.8  https://support.google.com/mail/?p=BadCredentials f20sm3302667lfm.71 - gsmtp')\n", "record": {"elapsed": {"repr": "0:00:33.665419", "seconds": 33.665419}, "exception": {"type": "SMTPAuthenticationError", "value": "(535, b'5.7.8 Username and Password not accepted. Learn more at\\n5.7.8  https://support.google.com/mail/?p=BadCredentials f20sm3302667lfm.71 - gsmtp')", "traceback": true}, "extra": {}, "file": {"name": "app.py", "path": "D:/nikita/tgbot/app.py"}, "function": "contact", "level": {"icon": "\u274c", "name": "ERROR", "no": 40}, "line": 65, "message": "An error has been caught in function 'contact', process 'MainProcess' (4940), thread 'WorkerThread2' (308):", "module": "app", "name": "__main__", "process": {"id": 4940, "name": "MainProcess"}, "thread": {"id": 308, "name": "WorkerThread2"}, "time": {"repr": "2021-02-02 15:56:46.388760+03:00", "timestamp": 1612270606.38876}}}
{"text": "2021-02-02T15:56:46.388760+0300 ERROR An error has been caught in function 'contact', process 'MainProcess' (4940), thread 'WorkerThread2' (308):\nTraceback (most recent call last):\n\n  File \"C:\\Users\\AV\\AppData\\Local\\Programs\\Python\\Python37\\lib\\threading.py\", line 890, in _bootstrap\n    self._bootstrap_inner()\n    |    -> <function Thread._bootstrap_inner at 0x0000012BFFDF1558>\n    -> <WorkerThread(WorkerThread2, started daemon 308)>\n\n  File \"C:\\Users\\AV\\AppData\\Local\\Programs\\Python\\Python37\\lib\\threading.py\", line 926, in _bootstrap_inner\n    self.run()\n    |    -> <function WorkerThread.run at 0x0000012B81E29D38>\n    -> <WorkerThread(WorkerThread2, started daemon 308)>\n\n  File \"D:\\nikita\\tgbot\\venv\\lib\\site-packages\\telebot\\util.py\", line 69, in run\n    task(*args, **kwargs)\n    |     |       -> {}\n    |     -> (<telebot.types.Message object at 0x0000012B8205C988>,)\n    -> <function message_start.<locals>.handle_query.<locals>.contact at 0x0000012B8213A8B8>\n\n> File \"D:/nikita/tgbot/app.py\", line 65, in contact\n    if mailing.send_mail(data=data):\n       |       |              -> {'phone': '79161583883', 'user_name': '\u25c7\u0421\u0443\u0449', 'call': '\u0424\u043e\u0440\u043c\u0430 \u0438\u0437 \u0441\u0442\u0430\u0440\u0442\u043e\u0432\u043e\u0433\u043e \u043c\u0435\u043d\u044e'}\n       |       -> <function send_mail at 0x0000012B820EF318>\n       -> <module 'services.mailing' from 'D:\\\\nikita\\\\tgbot\\\\services\\\\mailing.py'>\n\n  File \"D:\\nikita\\tgbot\\services\\mailing.py\", line 48, in send_mail\n    server.login(sender_email, password)\n    |      |     |             -> 'N546823791'\n    |      |     -> 'belinsky.dev@gmail.com'\n    |      -> <function SMTP.login at 0x0000012B81E9A168>\n    -> <smtplib.SMTP_SSL object at 0x0000012B82170388>\n\n  File \"C:\\Users\\AV\\AppData\\Local\\Programs\\Python\\Python37\\lib\\smtplib.py\", line 730, in login\n    raise last_exception\n          -> SMTPAuthenticationError(535, b'5.7.8 Username and Password not accepted. Learn more at\\n5.7.8  https://support.google.com/mai...\n\n  File \"C:\\Users\\AV\\AppData\\Local\\Programs\\Python\\Python37\\lib\\smtplib.py\", line 721, in login\n    initial_response_ok=initial_response_ok)\n                        -> True\n\n  File \"C:\\Users\\AV\\AppData\\Local\\Programs\\Python\\Python37\\lib\\smtplib.py\", line 642, in auth\n    raise SMTPAuthenticationError(code, resp)\n          |                       |     -> b'5.7.8 Username and Password not accepted. Learn more at\\n5.7.8  https://support.google.com/mail/?p=BadCredentials f20sm3302...\n          |                       -> 535\n          -> <class 'smtplib.SMTPAuthenticationError'>\n\nsmtplib.SMTPAuthenticationError: (535, b'5.7.8 Username and Password not accepted. Learn more at\\n5.7.8  https://support.google.com/mail/?p=BadCredentials f20sm3302667lfm.71 - gsmtp')\n", "record": {"elapsed": {"repr": "0:00:33.665419", "seconds": 33.665419}, "exception": {"type": "SMTPAuthenticationError", "value": "(535, b'5.7.8 Username and Password not accepted. Learn more at\\n5.7.8  https://support.google.com/mail/?p=BadCredentials f20sm3302667lfm.71 - gsmtp')", "traceback": true}, "extra": {}, "file": {"name": "app.py", "path": "D:/nikita/tgbot/app.py"}, "function": "contact", "level": {"icon": "\u274c", "name": "ERROR", "no": 40}, "line": 65, "message": "An error has been caught in function 'contact', process 'MainProcess' (4940), thread 'WorkerThread2' (308):", "module": "app", "name": "__main__", "process": {"id": 4940, "name": "MainProcess"}, "thread": {"id": 308, "name": "WorkerThread2"}, "time": {"repr": "2021-02-02 15:56:46.388760+03:00", "timestamp": 1612270606.38876}}}
{"text": "2021-02-02T15:59:27.120775+0300 ERROR An error has been caught in function 'contact', process 'MainProcess' (7600), thread 'WorkerThread1' (1324):\nTraceback (most recent call last):\n\n  File \"C:\\Users\\AV\\AppData\\Local\\Programs\\Python\\Python37\\lib\\threading.py\", line 890, in _bootstrap\n    self._bootstrap_inner()\n    |    -> <function Thread._bootstrap_inner at 0x00000259860F0B88>\n    -> <WorkerThread(WorkerThread1, started daemon 1324)>\n\n  File \"C:\\Users\\AV\\AppData\\Local\\Programs\\Python\\Python37\\lib\\threading.py\", line 926, in _bootstrap_inner\n    self.run()\n    |    -> <function WorkerThread.run at 0x0000025986CA5CA8>\n    -> <WorkerThread(WorkerThread1, started daemon 1324)>\n\n  File \"D:\\nikita\\tgbot\\venv\\lib\\site-packages\\telebot\\util.py\", line 69, in run\n    task(*args, **kwargs)\n    |     |       -> {}\n    |     -> (<telebot.types.Message object at 0x0000025986FE4B08>,)\n    -> <function message_start.<locals>.handle_query.<locals>.contact at 0x0000025986FB68B8>\n\n> File \"D:/nikita/tgbot/app.py\", line 67, in contact\n    mailing.send_mail(data=data)\n    |       |              -> {'phone': '79161583883', 'user_name': '\u25c7\u0421\u0443\u0449', 'call': '\u0424\u043e\u0440\u043c\u0430 \u0438\u0437 \u0441\u0442\u0430\u0440\u0442\u043e\u0432\u043e\u0433\u043e \u043c\u0435\u043d\u044e'}\n    |       -> <function send_mail at 0x0000025986F5B288>\n    -> <module 'services.mailing' from 'D:\\\\nikita\\\\tgbot\\\\services\\\\mailing.py'>\n\n  File \"D:\\nikita\\tgbot\\services\\mailing.py\", line 48, in send_mail\n    server.login(sender_email, password)\n    |      |     |             -> 'N546823791'\n    |      |     -> 'belinsky.dev@gmail.com'\n    |      -> <function SMTP.login at 0x0000025986D130D8>\n    -> <smtplib.SMTP_SSL object at 0x0000025986FECFC8>\n\n  File \"C:\\Users\\AV\\AppData\\Local\\Programs\\Python\\Python37\\lib\\smtplib.py\", line 730, in login\n    raise last_exception\n          -> SMTPAuthenticationError(535, b'5.7.8 Username and Password not accepted. Learn more at\\n5.7.8  https://support.google.com/mai...\n\n  File \"C:\\Users\\AV\\AppData\\Local\\Programs\\Python\\Python37\\lib\\smtplib.py\", line 721, in login\n    initial_response_ok=initial_response_ok)\n                        -> True\n\n  File \"C:\\Users\\AV\\AppData\\Local\\Programs\\Python\\Python37\\lib\\smtplib.py\", line 642, in auth\n    raise SMTPAuthenticationError(code, resp)\n          |                       |     -> b'5.7.8 Username and Password not accepted. Learn more at\\n5.7.8  https://support.google.com/mail/?p=BadCredentials l15sm3275...\n          |                       -> 535\n          -> <class 'smtplib.SMTPAuthenticationError'>\n\nsmtplib.SMTPAuthenticationError: (535, b'5.7.8 Username and Password not accepted. Learn more at\\n5.7.8  https://support.google.com/mail/?p=BadCredentials l15sm3275302lfg.272 - gsmtp')\n", "record": {"elapsed": {"repr": "0:00:17.540811", "seconds": 17.540811}, "exception": {"type": "SMTPAuthenticationError", "value": "(535, b'5.7.8 Username and Password not accepted. Learn more at\\n5.7.8  https://support.google.com/mail/?p=BadCredentials l15sm3275302lfg.272 - gsmtp')", "traceback": true}, "extra": {}, "file": {"name": "app.py", "path": "D:/nikita/tgbot/app.py"}, "function": "contact", "level": {"icon": "\u274c", "name": "ERROR", "no": 40}, "line": 67, "message": "An error has been caught in function 'contact', process 'MainProcess' (7600), thread 'WorkerThread1' (1324):", "module": "app", "name": "__main__", "process": {"id": 7600, "name": "MainProcess"}, "thread": {"id": 1324, "name": "WorkerThread1"}, "time": {"repr": "2021-02-02 15:59:27.120775+03:00", "timestamp": 1612270767.120775}}}
{"text": "2021-02-02T15:59:27.120775+0300 ERROR An error has been caught in function 'contact', process 'MainProcess' (7600), thread 'WorkerThread1' (1324):\nTraceback (most recent call last):\n\n  File \"C:\\Users\\AV\\AppData\\Local\\Programs\\Python\\Python37\\lib\\threading.py\", line 890, in _bootstrap\n    self._bootstrap_inner()\n    |    -> <function Thread._bootstrap_inner at 0x00000259860F0B88>\n    -> <WorkerThread(WorkerThread1, started daemon 1324)>\n\n  File \"C:\\Users\\AV\\AppData\\Local\\Programs\\Python\\Python37\\lib\\threading.py\", line 926, in _bootstrap_inner\n    self.run()\n    |    -> <function WorkerThread.run at 0x0000025986CA5CA8>\n    -> <WorkerThread(WorkerThread1, started daemon 1324)>\n\n  File \"D:\\nikita\\tgbot\\venv\\lib\\site-packages\\telebot\\util.py\", line 69, in run\n    task(*args, **kwargs)\n    |     |       -> {}\n    |     -> (<telebot.types.Message object at 0x0000025986FE4B08>,)\n    -> <function message_start.<locals>.handle_query.<locals>.contact at 0x0000025986FB68B8>\n\n> File \"D:/nikita/tgbot/app.py\", line 67, in contact\n    mailing.send_mail(data=data)\n    |       |              -> {'phone': '79161583883', 'user_name': '\u25c7\u0421\u0443\u0449', 'call': '\u0424\u043e\u0440\u043c\u0430 \u0438\u0437 \u0441\u0442\u0430\u0440\u0442\u043e\u0432\u043e\u0433\u043e \u043c\u0435\u043d\u044e'}\n    |       -> <function send_mail at 0x0000025986F5B288>\n    -> <module 'services.mailing' from 'D:\\\\nikita\\\\tgbot\\\\services\\\\mailing.py'>\n\n  File \"D:\\nikita\\tgbot\\services\\mailing.py\", line 48, in send_mail\n    server.login(sender_email, password)\n    |      |     |             -> 'N546823791'\n    |      |     -> 'belinsky.dev@gmail.com'\n    |      -> <function SMTP.login at 0x0000025986D130D8>\n    -> <smtplib.SMTP_SSL object at 0x0000025986FECFC8>\n\n  File \"C:\\Users\\AV\\AppData\\Local\\Programs\\Python\\Python37\\lib\\smtplib.py\", line 730, in login\n    raise last_exception\n          -> SMTPAuthenticationError(535, b'5.7.8 Username and Password not accepted. Learn more at\\n5.7.8  https://support.google.com/mai...\n\n  File \"C:\\Users\\AV\\AppData\\Local\\Programs\\Python\\Python37\\lib\\smtplib.py\", line 721, in login\n    initial_response_ok=initial_response_ok)\n                        -> True\n\n  File \"C:\\Users\\AV\\AppData\\Local\\Programs\\Python\\Python37\\lib\\smtplib.py\", line 642, in auth\n    raise SMTPAuthenticationError(code, resp)\n          |                       |     -> b'5.7.8 Username and Password not accepted. Learn more at\\n5.7.8  https://support.google.com/mail/?p=BadCredentials l15sm3275...\n          |                       -> 535\n          -> <class 'smtplib.SMTPAuthenticationError'>\n\nsmtplib.SMTPAuthenticationError: (535, b'5.7.8 Username and Password not accepted. Learn more at\\n5.7.8  https://support.google.com/mail/?p=BadCredentials l15sm3275302lfg.272 - gsmtp')\n", "record": {"elapsed": {"repr": "0:00:17.540811", "seconds": 17.540811}, "exception": {"type": "SMTPAuthenticationError", "value": "(535, b'5.7.8 Username and Password not accepted. Learn more at\\n5.7.8  https://support.google.com/mail/?p=BadCredentials l15sm3275302lfg.272 - gsmtp')", "traceback": true}, "extra": {}, "file": {"name": "app.py", "path": "D:/nikita/tgbot/app.py"}, "function": "contact", "level": {"icon": "\u274c", "name": "ERROR", "no": 40}, "line": 67, "message": "An error has been caught in function 'contact', process 'MainProcess' (7600), thread 'WorkerThread1' (1324):", "module": "app", "name": "__main__", "process": {"id": 7600, "name": "MainProcess"}, "thread": {"id": 1324, "name": "WorkerThread1"}, "time": {"repr": "2021-02-02 15:59:27.120775+03:00", "timestamp": 1612270767.120775}}}
{"text": "2021-02-02T16:00:20.421821+0300 ERROR An error has been caught in function 'contact', process 'MainProcess' (120), thread 'WorkerThread1' (5724):\nTraceback (most recent call last):\n\n  File \"C:\\Users\\AV\\AppData\\Local\\Programs\\Python\\Python37\\lib\\threading.py\", line 890, in _bootstrap\n    self._bootstrap_inner()\n    |    -> <function Thread._bootstrap_inner at 0x000001FA34DC0B88>\n    -> <WorkerThread(WorkerThread1, started daemon 5724)>\n\n  File \"C:\\Users\\AV\\AppData\\Local\\Programs\\Python\\Python37\\lib\\threading.py\", line 926, in _bootstrap_inner\n    self.run()\n    |    -> <function WorkerThread.run at 0x000001FA35965CA8>\n    -> <WorkerThread(WorkerThread1, started daemon 5724)>\n\n  File \"D:\\nikita\\tgbot\\venv\\lib\\site-packages\\telebot\\util.py\", line 69, in run\n    task(*args, **kwargs)\n    |     |       -> {}\n    |     -> (<telebot.types.Message object at 0x000001FA35CB0CC8>,)\n    -> <function message_start.<locals>.handle_query.<locals>.contact at 0x000001FA35C75B88>\n\n> File \"D:/nikita/tgbot/app.py\", line 66, in contact\n    if mailing.send_mail(data=data):\n       |       |              -> {'phone': '79161583883', 'user_name': '\u25c7\u0421\u0443\u0449', 'call': '\u0424\u043e\u0440\u043c\u0430 \u0438\u0437 \u0441\u0442\u0430\u0440\u0442\u043e\u0432\u043e\u0433\u043e \u043c\u0435\u043d\u044e'}\n       |       -> <function send_mail at 0x000001FA35C1B288>\n       -> <module 'services.mailing' from 'D:\\\\nikita\\\\tgbot\\\\services\\\\mailing.py'>\n\n  File \"D:\\nikita\\tgbot\\services\\mailing.py\", line 48, in send_mail\n    server.login(sender_email, password)\n    |      |     |             -> 'N546823791'\n    |      |     -> 'belinsky.dev@gmail.com'\n    |      -> <function SMTP.login at 0x000001FA359D30D8>\n    -> <smtplib.SMTP_SSL object at 0x000001FA35C9C348>\n\n  File \"C:\\Users\\AV\\AppData\\Local\\Programs\\Python\\Python37\\lib\\smtplib.py\", line 730, in login\n    raise last_exception\n          -> SMTPAuthenticationError(535, b'5.7.8 Username and Password not accepted. Learn more at\\n5.7.8  https://support.google.com/mai...\n\n  File \"C:\\Users\\AV\\AppData\\Local\\Programs\\Python\\Python37\\lib\\smtplib.py\", line 721, in login\n    initial_response_ok=initial_response_ok)\n                        -> True\n\n  File \"C:\\Users\\AV\\AppData\\Local\\Programs\\Python\\Python37\\lib\\smtplib.py\", line 642, in auth\n    raise SMTPAuthenticationError(code, resp)\n          |                       |     -> b'5.7.8 Username and Password not accepted. Learn more at\\n5.7.8  https://support.google.com/mail/?p=BadCredentials v25sm4299...\n          |                       -> 535\n          -> <class 'smtplib.SMTPAuthenticationError'>\n\nsmtplib.SMTPAuthenticationError: (535, b'5.7.8 Username and Password not accepted. Learn more at\\n5.7.8  https://support.google.com/mail/?p=BadCredentials v25sm4299145lji.85 - gsmtp')\n", "record": {"elapsed": {"repr": "0:00:17.987072", "seconds": 17.987072}, "exception": {"type": "SMTPAuthenticationError", "value": "(535, b'5.7.8 Username and Password not accepted. Learn more at\\n5.7.8  https://support.google.com/mail/?p=BadCredentials v25sm4299145lji.85 - gsmtp')", "traceback": true}, "extra": {}, "file": {"name": "app.py", "path": "D:/nikita/tgbot/app.py"}, "function": "contact", "level": {"icon": "\u274c", "name": "ERROR", "no": 40}, "line": 66, "message": "An error has been caught in function 'contact', process 'MainProcess' (120), thread 'WorkerThread1' (5724):", "module": "app", "name": "__main__", "process": {"id": 120, "name": "MainProcess"}, "thread": {"id": 5724, "name": "WorkerThread1"}, "time": {"repr": "2021-02-02 16:00:20.421821+03:00", "timestamp": 1612270820.421821}}}
{"text": "2021-02-02T16:00:20.421821+0300 ERROR An error has been caught in function 'contact', process 'MainProcess' (120), thread 'WorkerThread1' (5724):\nTraceback (most recent call last):\n\n  File \"C:\\Users\\AV\\AppData\\Local\\Programs\\Python\\Python37\\lib\\threading.py\", line 890, in _bootstrap\n    self._bootstrap_inner()\n    |    -> <function Thread._bootstrap_inner at 0x000001FA34DC0B88>\n    -> <WorkerThread(WorkerThread1, started daemon 5724)>\n\n  File \"C:\\Users\\AV\\AppData\\Local\\Programs\\Python\\Python37\\lib\\threading.py\", line 926, in _bootstrap_inner\n    self.run()\n    |    -> <function WorkerThread.run at 0x000001FA35965CA8>\n    -> <WorkerThread(WorkerThread1, started daemon 5724)>\n\n  File \"D:\\nikita\\tgbot\\venv\\lib\\site-packages\\telebot\\util.py\", line 69, in run\n    task(*args, **kwargs)\n    |     |       -> {}\n    |     -> (<telebot.types.Message object at 0x000001FA35CB0CC8>,)\n    -> <function message_start.<locals>.handle_query.<locals>.contact at 0x000001FA35C75B88>\n\n> File \"D:/nikita/tgbot/app.py\", line 66, in contact\n    if mailing.send_mail(data=data):\n       |       |              -> {'phone': '79161583883', 'user_name': '\u25c7\u0421\u0443\u0449', 'call': '\u0424\u043e\u0440\u043c\u0430 \u0438\u0437 \u0441\u0442\u0430\u0440\u0442\u043e\u0432\u043e\u0433\u043e \u043c\u0435\u043d\u044e'}\n       |       -> <function send_mail at 0x000001FA35C1B288>\n       -> <module 'services.mailing' from 'D:\\\\nikita\\\\tgbot\\\\services\\\\mailing.py'>\n\n  File \"D:\\nikita\\tgbot\\services\\mailing.py\", line 48, in send_mail\n    server.login(sender_email, password)\n    |      |     |             -> 'N546823791'\n    |      |     -> 'belinsky.dev@gmail.com'\n    |      -> <function SMTP.login at 0x000001FA359D30D8>\n    -> <smtplib.SMTP_SSL object at 0x000001FA35C9C348>\n\n  File \"C:\\Users\\AV\\AppData\\Local\\Programs\\Python\\Python37\\lib\\smtplib.py\", line 730, in login\n    raise last_exception\n          -> SMTPAuthenticationError(535, b'5.7.8 Username and Password not accepted. Learn more at\\n5.7.8  https://support.google.com/mai...\n\n  File \"C:\\Users\\AV\\AppData\\Local\\Programs\\Python\\Python37\\lib\\smtplib.py\", line 721, in login\n    initial_response_ok=initial_response_ok)\n                        -> True\n\n  File \"C:\\Users\\AV\\AppData\\Local\\Programs\\Python\\Python37\\lib\\smtplib.py\", line 642, in auth\n    raise SMTPAuthenticationError(code, resp)\n          |                       |     -> b'5.7.8 Username and Password not accepted. Learn more at\\n5.7.8  https://support.google.com/mail/?p=BadCredentials v25sm4299...\n          |                       -> 535\n          -> <class 'smtplib.SMTPAuthenticationError'>\n\nsmtplib.SMTPAuthenticationError: (535, b'5.7.8 Username and Password not accepted. Learn more at\\n5.7.8  https://support.google.com/mail/?p=BadCredentials v25sm4299145lji.85 - gsmtp')\n", "record": {"elapsed": {"repr": "0:00:17.987072", "seconds": 17.987072}, "exception": {"type": "SMTPAuthenticationError", "value": "(535, b'5.7.8 Username and Password not accepted. Learn more at\\n5.7.8  https://support.google.com/mail/?p=BadCredentials v25sm4299145lji.85 - gsmtp')", "traceback": true}, "extra": {}, "file": {"name": "app.py", "path": "D:/nikita/tgbot/app.py"}, "function": "contact", "level": {"icon": "\u274c", "name": "ERROR", "no": 40}, "line": 66, "message": "An error has been caught in function 'contact', process 'MainProcess' (120), thread 'WorkerThread1' (5724):", "module": "app", "name": "__main__", "process": {"id": 120, "name": "MainProcess"}, "thread": {"id": 5724, "name": "WorkerThread1"}, "time": {"repr": "2021-02-02 16:00:20.421821+03:00", "timestamp": 1612270820.421821}}}
{"text": "2021-02-02T16:04:51.732786+0300 ERROR An error has been caught in function 'contact', process 'MainProcess' (1856), thread 'WorkerThread2' (2484):\nTraceback (most recent call last):\n\n  File \"C:\\Users\\AV\\AppData\\Local\\Programs\\Python\\Python37\\lib\\threading.py\", line 890, in _bootstrap\n    self._bootstrap_inner()\n    |    -> <function Thread._bootstrap_inner at 0x000001FFCAB60AF8>\n    -> <WorkerThread(WorkerThread2, started daemon 2484)>\n\n  File \"C:\\Users\\AV\\AppData\\Local\\Programs\\Python\\Python37\\lib\\threading.py\", line 926, in _bootstrap_inner\n    self.run()\n    |    -> <function WorkerThread.run at 0x000001FFCB725C18>\n    -> <WorkerThread(WorkerThread2, started daemon 2484)>\n\n  File \"D:\\nikita\\tgbot\\venv\\lib\\site-packages\\telebot\\util.py\", line 69, in run\n    task(*args, **kwargs)\n    |     |       -> {}\n    |     -> (<telebot.types.Message object at 0x000001FFCBA5C588>,)\n    -> <function message_start.<locals>.handle_query.<locals>.contact at 0x000001FFCBA35E58>\n\n> File \"D:/nikita/tgbot/app.py\", line 66, in contact\n    if mailing.send_mail(data=data):\n       |       |              -> {'phone': '79161583883', 'user_name': '\u25c7\u0421\u0443\u0449', 'call': '\u0424\u043e\u0440\u043c\u0430 \u0438\u0437 \u0441\u0442\u0430\u0440\u0442\u043e\u0432\u043e\u0433\u043e \u043c\u0435\u043d\u044e'}\n       |       -> <function send_mail at 0x000001FFCB9DB1F8>\n       -> <module 'services.mailing' from 'D:\\\\nikita\\\\tgbot\\\\services\\\\mailing.py'>\n\n  File \"D:\\nikita\\tgbot\\services\\mailing.py\", line 48, in send_mail\n    server.login(sender_email, password)\n    |      |     |             -> 'N546823791'\n    |      |     -> 'belinsky.dev@gmail.com'\n    |      -> <function SMTP.login at 0x000001FFCB793048>\n    -> <smtplib.SMTP_SSL object at 0x000001FFCBA6DDC8>\n\n  File \"C:\\Users\\AV\\AppData\\Local\\Programs\\Python\\Python37\\lib\\smtplib.py\", line 730, in login\n    raise last_exception\n          -> SMTPAuthenticationError(535, b'5.7.8 Username and Password not accepted. Learn more at\\n5.7.8  https://support.google.com/mai...\n\n  File \"C:\\Users\\AV\\AppData\\Local\\Programs\\Python\\Python37\\lib\\smtplib.py\", line 721, in login\n    initial_response_ok=initial_response_ok)\n                        -> True\n\n  File \"C:\\Users\\AV\\AppData\\Local\\Programs\\Python\\Python37\\lib\\smtplib.py\", line 642, in auth\n    raise SMTPAuthenticationError(code, resp)\n          |                       |     -> b'5.7.8 Username and Password not accepted. Learn more at\\n5.7.8  https://support.google.com/mail/?p=BadCredentials v25sm4300...\n          |                       -> 535\n          -> <class 'smtplib.SMTPAuthenticationError'>\n\nsmtplib.SMTPAuthenticationError: (535, b'5.7.8 Username and Password not accepted. Learn more at\\n5.7.8  https://support.google.com/mail/?p=BadCredentials v25sm4300425lji.85 - gsmtp')\n", "record": {"elapsed": {"repr": "0:00:14.840091", "seconds": 14.840091}, "exception": {"type": "SMTPAuthenticationError", "value": "(535, b'5.7.8 Username and Password not accepted. Learn more at\\n5.7.8  https://support.google.com/mail/?p=BadCredentials v25sm4300425lji.85 - gsmtp')", "traceback": true}, "extra": {}, "file": {"name": "app.py", "path": "D:/nikita/tgbot/app.py"}, "function": "contact", "level": {"icon": "\u274c", "name": "ERROR", "no": 40}, "line": 66, "message": "An error has been caught in function 'contact', process 'MainProcess' (1856), thread 'WorkerThread2' (2484):", "module": "app", "name": "__main__", "process": {"id": 1856, "name": "MainProcess"}, "thread": {"id": 2484, "name": "WorkerThread2"}, "time": {"repr": "2021-02-02 16:04:51.732786+03:00", "timestamp": 1612271091.732786}}}
{"text": "2021-02-02T16:04:51.732786+0300 ERROR An error has been caught in function 'contact', process 'MainProcess' (1856), thread 'WorkerThread2' (2484):\nTraceback (most recent call last):\n\n  File \"C:\\Users\\AV\\AppData\\Local\\Programs\\Python\\Python37\\lib\\threading.py\", line 890, in _bootstrap\n    self._bootstrap_inner()\n    |    -> <function Thread._bootstrap_inner at 0x000001FFCAB60AF8>\n    -> <WorkerThread(WorkerThread2, started daemon 2484)>\n\n  File \"C:\\Users\\AV\\AppData\\Local\\Programs\\Python\\Python37\\lib\\threading.py\", line 926, in _bootstrap_inner\n    self.run()\n    |    -> <function WorkerThread.run at 0x000001FFCB725C18>\n    -> <WorkerThread(WorkerThread2, started daemon 2484)>\n\n  File \"D:\\nikita\\tgbot\\venv\\lib\\site-packages\\telebot\\util.py\", line 69, in run\n    task(*args, **kwargs)\n    |     |       -> {}\n    |     -> (<telebot.types.Message object at 0x000001FFCBA5C588>,)\n    -> <function message_start.<locals>.handle_query.<locals>.contact at 0x000001FFCBA35E58>\n\n> File \"D:/nikita/tgbot/app.py\", line 66, in contact\n    if mailing.send_mail(data=data):\n       |       |              -> {'phone': '79161583883', 'user_name': '\u25c7\u0421\u0443\u0449', 'call': '\u0424\u043e\u0440\u043c\u0430 \u0438\u0437 \u0441\u0442\u0430\u0440\u0442\u043e\u0432\u043e\u0433\u043e \u043c\u0435\u043d\u044e'}\n       |       -> <function send_mail at 0x000001FFCB9DB1F8>\n       -> <module 'services.mailing' from 'D:\\\\nikita\\\\tgbot\\\\services\\\\mailing.py'>\n\n  File \"D:\\nikita\\tgbot\\services\\mailing.py\", line 48, in send_mail\n    server.login(sender_email, password)\n    |      |     |             -> 'N546823791'\n    |      |     -> 'belinsky.dev@gmail.com'\n    |      -> <function SMTP.login at 0x000001FFCB793048>\n    -> <smtplib.SMTP_SSL object at 0x000001FFCBA6DDC8>\n\n  File \"C:\\Users\\AV\\AppData\\Local\\Programs\\Python\\Python37\\lib\\smtplib.py\", line 730, in login\n    raise last_exception\n          -> SMTPAuthenticationError(535, b'5.7.8 Username and Password not accepted. Learn more at\\n5.7.8  https://support.google.com/mai...\n\n  File \"C:\\Users\\AV\\AppData\\Local\\Programs\\Python\\Python37\\lib\\smtplib.py\", line 721, in login\n    initial_response_ok=initial_response_ok)\n                        -> True\n\n  File \"C:\\Users\\AV\\AppData\\Local\\Programs\\Python\\Python37\\lib\\smtplib.py\", line 642, in auth\n    raise SMTPAuthenticationError(code, resp)\n          |                       |     -> b'5.7.8 Username and Password not accepted. Learn more at\\n5.7.8  https://support.google.com/mail/?p=BadCredentials v25sm4300...\n          |                       -> 535\n          -> <class 'smtplib.SMTPAuthenticationError'>\n\nsmtplib.SMTPAuthenticationError: (535, b'5.7.8 Username and Password not accepted. Learn more at\\n5.7.8  https://support.google.com/mail/?p=BadCredentials v25sm4300425lji.85 - gsmtp')\n", "record": {"elapsed": {"repr": "0:00:14.840091", "seconds": 14.840091}, "exception": {"type": "SMTPAuthenticationError", "value": "(535, b'5.7.8 Username and Password not accepted. Learn more at\\n5.7.8  https://support.google.com/mail/?p=BadCredentials v25sm4300425lji.85 - gsmtp')", "traceback": true}, "extra": {}, "file": {"name": "app.py", "path": "D:/nikita/tgbot/app.py"}, "function": "contact", "level": {"icon": "\u274c", "name": "ERROR", "no": 40}, "line": 66, "message": "An error has been caught in function 'contact', process 'MainProcess' (1856), thread 'WorkerThread2' (2484):", "module": "app", "name": "__main__", "process": {"id": 1856, "name": "MainProcess"}, "thread": {"id": 2484, "name": "WorkerThread2"}, "time": {"repr": "2021-02-02 16:04:51.732786+03:00", "timestamp": 1612271091.732786}}}
{"text": "2021-02-02T16:12:54.602085+0300 ERROR An error has been caught in function 'contact', process 'MainProcess' (12268), thread 'WorkerThread1' (12284):\nTraceback (most recent call last):\n\n  File \"C:\\Users\\AV\\AppData\\Local\\Programs\\Python\\Python37\\lib\\threading.py\", line 890, in _bootstrap\n    self._bootstrap_inner()\n    |    -> <function Thread._bootstrap_inner at 0x0000025EA4F70AF8>\n    -> <WorkerThread(WorkerThread1, started daemon 12284)>\n\n  File \"C:\\Users\\AV\\AppData\\Local\\Programs\\Python\\Python37\\lib\\threading.py\", line 926, in _bootstrap_inner\n    self.run()\n    |    -> <function WorkerThread.run at 0x0000025EA5B25C18>\n    -> <WorkerThread(WorkerThread1, started daemon 12284)>\n\n  File \"D:\\nikita\\tgbot\\venv\\lib\\site-packages\\telebot\\util.py\", line 69, in run\n    task(*args, **kwargs)\n    |     |       -> {}\n    |     -> (<telebot.types.Message object at 0x0000025EA5E6A488>,)\n    -> <function message_start.<locals>.handle_query.<locals>.contact at 0x0000025EA5E8A048>\n\n> File \"D:/nikita/tgbot/app.py\", line 67, in contact\n    if mailing.send_mail(data=data):\n       |       |              -> {'phone': '79161583883', 'user_name': '\u25c7\u0421\u0443\u0449', 'call': '\u0424\u043e\u0440\u043c\u0430 \u0438\u0437 \u0441\u0442\u0430\u0440\u0442\u043e\u0432\u043e\u0433\u043e \u043c\u0435\u043d\u044e'}\n       |       -> <function send_mail at 0x0000025EA5E14318>\n       -> <module 'services.mailing' from 'D:\\\\nikita\\\\tgbot\\\\services\\\\mailing.py'>\n\n  File \"D:\\nikita\\tgbot\\services\\mailing.py\", line 50, in send_mail\n    server.login(sender_email, password)\n    |      |     |             -> 'N546823791'\n    |      |     -> 'belinsky.dev@gmail.com'\n    |      -> <function SMTP.login at 0x0000025EA5BAD168>\n    -> <smtplib.SMTP_SSL object at 0x0000025EA5E84FC8>\n\n  File \"C:\\Users\\AV\\AppData\\Local\\Programs\\Python\\Python37\\lib\\smtplib.py\", line 730, in login\n    raise last_exception\n          -> SMTPAuthenticationError(535, b'5.7.8 Username and Password not accepted. Learn more at\\n5.7.8  https://support.google.com/mai...\n\n  File \"C:\\Users\\AV\\AppData\\Local\\Programs\\Python\\Python37\\lib\\smtplib.py\", line 721, in login\n    initial_response_ok=initial_response_ok)\n                        -> True\n\n  File \"C:\\Users\\AV\\AppData\\Local\\Programs\\Python\\Python37\\lib\\smtplib.py\", line 642, in auth\n    raise SMTPAuthenticationError(code, resp)\n          |                       |     -> b'5.7.8 Username and Password not accepted. Learn more at\\n5.7.8  https://support.google.com/mail/?p=BadCredentials p14sm4379...\n          |                       -> 535\n          -> <class 'smtplib.SMTPAuthenticationError'>\n\nsmtplib.SMTPAuthenticationError: (535, b'5.7.8 Username and Password not accepted. Learn more at\\n5.7.8  https://support.google.com/mail/?p=BadCredentials p14sm4379009lji.0 - gsmtp')\n", "record": {"elapsed": {"repr": "0:00:15.940970", "seconds": 15.94097}, "exception": {"type": "SMTPAuthenticationError", "value": "(535, b'5.7.8 Username and Password not accepted. Learn more at\\n5.7.8  https://support.google.com/mail/?p=BadCredentials p14sm4379009lji.0 - gsmtp')", "traceback": true}, "extra": {}, "file": {"name": "app.py", "path": "D:/nikita/tgbot/app.py"}, "function": "contact", "level": {"icon": "\u274c", "name": "ERROR", "no": 40}, "line": 67, "message": "An error has been caught in function 'contact', process 'MainProcess' (12268), thread 'WorkerThread1' (12284):", "module": "app", "name": "__main__", "process": {"id": 12268, "name": "MainProcess"}, "thread": {"id": 12284, "name": "WorkerThread1"}, "time": {"repr": "2021-02-02 16:12:54.602085+03:00", "timestamp": 1612271574.602085}}}
{"text": "2021-02-02T16:12:54.602085+0300 ERROR An error has been caught in function 'contact', process 'MainProcess' (12268), thread 'WorkerThread1' (12284):\nTraceback (most recent call last):\n\n  File \"C:\\Users\\AV\\AppData\\Local\\Programs\\Python\\Python37\\lib\\threading.py\", line 890, in _bootstrap\n    self._bootstrap_inner()\n    |    -> <function Thread._bootstrap_inner at 0x0000025EA4F70AF8>\n    -> <WorkerThread(WorkerThread1, started daemon 12284)>\n\n  File \"C:\\Users\\AV\\AppData\\Local\\Programs\\Python\\Python37\\lib\\threading.py\", line 926, in _bootstrap_inner\n    self.run()\n    |    -> <function WorkerThread.run at 0x0000025EA5B25C18>\n    -> <WorkerThread(WorkerThread1, started daemon 12284)>\n\n  File \"D:\\nikita\\tgbot\\venv\\lib\\site-packages\\telebot\\util.py\", line 69, in run\n    task(*args, **kwargs)\n    |     |       -> {}\n    |     -> (<telebot.types.Message object at 0x0000025EA5E6A488>,)\n    -> <function message_start.<locals>.handle_query.<locals>.contact at 0x0000025EA5E8A048>\n\n> File \"D:/nikita/tgbot/app.py\", line 67, in contact\n    if mailing.send_mail(data=data):\n       |       |              -> {'phone': '79161583883', 'user_name': '\u25c7\u0421\u0443\u0449', 'call': '\u0424\u043e\u0440\u043c\u0430 \u0438\u0437 \u0441\u0442\u0430\u0440\u0442\u043e\u0432\u043e\u0433\u043e \u043c\u0435\u043d\u044e'}\n       |       -> <function send_mail at 0x0000025EA5E14318>\n       -> <module 'services.mailing' from 'D:\\\\nikita\\\\tgbot\\\\services\\\\mailing.py'>\n\n  File \"D:\\nikita\\tgbot\\services\\mailing.py\", line 50, in send_mail\n    server.login(sender_email, password)\n    |      |     |             -> 'N546823791'\n    |      |     -> 'belinsky.dev@gmail.com'\n    |      -> <function SMTP.login at 0x0000025EA5BAD168>\n    -> <smtplib.SMTP_SSL object at 0x0000025EA5E84FC8>\n\n  File \"C:\\Users\\AV\\AppData\\Local\\Programs\\Python\\Python37\\lib\\smtplib.py\", line 730, in login\n    raise last_exception\n          -> SMTPAuthenticationError(535, b'5.7.8 Username and Password not accepted. Learn more at\\n5.7.8  https://support.google.com/mai...\n\n  File \"C:\\Users\\AV\\AppData\\Local\\Programs\\Python\\Python37\\lib\\smtplib.py\", line 721, in login\n    initial_response_ok=initial_response_ok)\n                        -> True\n\n  File \"C:\\Users\\AV\\AppData\\Local\\Programs\\Python\\Python37\\lib\\smtplib.py\", line 642, in auth\n    raise SMTPAuthenticationError(code, resp)\n          |                       |     -> b'5.7.8 Username and Password not accepted. Learn more at\\n5.7.8  https://support.google.com/mail/?p=BadCredentials p14sm4379...\n          |                       -> 535\n          -> <class 'smtplib.SMTPAuthenticationError'>\n\nsmtplib.SMTPAuthenticationError: (535, b'5.7.8 Username and Password not accepted. Learn more at\\n5.7.8  https://support.google.com/mail/?p=BadCredentials p14sm4379009lji.0 - gsmtp')\n", "record": {"elapsed": {"repr": "0:00:15.940970", "seconds": 15.94097}, "exception": {"type": "SMTPAuthenticationError", "value": "(535, b'5.7.8 Username and Password not accepted. Learn more at\\n5.7.8  https://support.google.com/mail/?p=BadCredentials p14sm4379009lji.0 - gsmtp')", "traceback": true}, "extra": {}, "file": {"name": "app.py", "path": "D:/nikita/tgbot/app.py"}, "function": "contact", "level": {"icon": "\u274c", "name": "ERROR", "no": 40}, "line": 67, "message": "An error has been caught in function 'contact', process 'MainProcess' (12268), thread 'WorkerThread1' (12284):", "module": "app", "name": "__main__", "process": {"id": 12268, "name": "MainProcess"}, "thread": {"id": 12284, "name": "WorkerThread1"}, "time": {"repr": "2021-02-02 16:12:54.602085+03:00", "timestamp": 1612271574.602085}}}
{"text": "2021-02-02T16:13:48.414553+0300 ERROR An error has been caught in function 'contact', process 'MainProcess' (1976), thread 'WorkerThread2' (12060):\nTraceback (most recent call last):\n\n  File \"C:\\Users\\AV\\AppData\\Local\\Programs\\Python\\Python37\\lib\\threading.py\", line 890, in _bootstrap\n    self._bootstrap_inner()\n    |    -> <function Thread._bootstrap_inner at 0x000002756DEC0AF8>\n    -> <WorkerThread(WorkerThread2, started daemon 12060)>\n\n  File \"C:\\Users\\AV\\AppData\\Local\\Programs\\Python\\Python37\\lib\\threading.py\", line 926, in _bootstrap_inner\n    self.run()\n    |    -> <function WorkerThread.run at 0x000002756EA65C18>\n    -> <WorkerThread(WorkerThread2, started daemon 12060)>\n\n  File \"D:\\nikita\\tgbot\\venv\\lib\\site-packages\\telebot\\util.py\", line 69, in run\n    task(*args, **kwargs)\n    |     |       -> {}\n    |     -> (<telebot.types.Message object at 0x000002756ED95F08>,)\n    -> <function message_start.<locals>.handle_query.<locals>.contact at 0x000002756EDAE0D8>\n\n> File \"D:/nikita/tgbot/app.py\", line 67, in contact\n    if mailing.send_mail(data=data):\n       |       |              -> {'phone': '79161583883', 'user_name': '\u25c7\u0421\u0443\u0449', 'call': '\u0424\u043e\u0440\u043c\u0430 \u0438\u0437 \u0441\u0442\u0430\u0440\u0442\u043e\u0432\u043e\u0433\u043e \u043c\u0435\u043d\u044e'}\n       |       -> <function send_mail at 0x000002756ED1B318>\n       -> <module 'services.mailing' from 'D:\\\\nikita\\\\tgbot\\\\services\\\\mailing.py'>\n\n  File \"D:\\nikita\\tgbot\\services\\mailing.py\", line 50, in send_mail\n    server.login(sender_email, password)\n    |      |     |             -> 'N546823791'\n    |      |     -> 'belinsky.dev@gmail.com'\n    |      -> <function SMTP.login at 0x000002756EAD3168>\n    -> <smtplib.SMTP_SSL object at 0x000002756EDB3148>\n\n  File \"C:\\Users\\AV\\AppData\\Local\\Programs\\Python\\Python37\\lib\\smtplib.py\", line 730, in login\n    raise last_exception\n          -> SMTPAuthenticationError(535, b'5.7.8 Username and Password not accepted. Learn more at\\n5.7.8  https://support.google.com/mai...\n\n  File \"C:\\Users\\AV\\AppData\\Local\\Programs\\Python\\Python37\\lib\\smtplib.py\", line 721, in login\n    initial_response_ok=initial_response_ok)\n                        -> True\n\n  File \"C:\\Users\\AV\\AppData\\Local\\Programs\\Python\\Python37\\lib\\smtplib.py\", line 642, in auth\n    raise SMTPAuthenticationError(code, resp)\n          |                       |     -> b'5.7.8 Username and Password not accepted. Learn more at\\n5.7.8  https://support.google.com/mail/?p=BadCredentials v29sm3336...\n          |                       -> 535\n          -> <class 'smtplib.SMTPAuthenticationError'>\n\nsmtplib.SMTPAuthenticationError: (535, b'5.7.8 Username and Password not accepted. Learn more at\\n5.7.8  https://support.google.com/mail/?p=BadCredentials v29sm3336824lfq.230 - gsmtp')\n", "record": {"elapsed": {"repr": "0:00:17.241840", "seconds": 17.24184}, "exception": {"type": "SMTPAuthenticationError", "value": "(535, b'5.7.8 Username and Password not accepted. Learn more at\\n5.7.8  https://support.google.com/mail/?p=BadCredentials v29sm3336824lfq.230 - gsmtp')", "traceback": true}, "extra": {}, "file": {"name": "app.py", "path": "D:/nikita/tgbot/app.py"}, "function": "contact", "level": {"icon": "\u274c", "name": "ERROR", "no": 40}, "line": 67, "message": "An error has been caught in function 'contact', process 'MainProcess' (1976), thread 'WorkerThread2' (12060):", "module": "app", "name": "__main__", "process": {"id": 1976, "name": "MainProcess"}, "thread": {"id": 12060, "name": "WorkerThread2"}, "time": {"repr": "2021-02-02 16:13:48.414553+03:00", "timestamp": 1612271628.414553}}}
{"text": "2021-02-02T16:13:48.414553+0300 ERROR An error has been caught in function 'contact', process 'MainProcess' (1976), thread 'WorkerThread2' (12060):\nTraceback (most recent call last):\n\n  File \"C:\\Users\\AV\\AppData\\Local\\Programs\\Python\\Python37\\lib\\threading.py\", line 890, in _bootstrap\n    self._bootstrap_inner()\n    |    -> <function Thread._bootstrap_inner at 0x000002756DEC0AF8>\n    -> <WorkerThread(WorkerThread2, started daemon 12060)>\n\n  File \"C:\\Users\\AV\\AppData\\Local\\Programs\\Python\\Python37\\lib\\threading.py\", line 926, in _bootstrap_inner\n    self.run()\n    |    -> <function WorkerThread.run at 0x000002756EA65C18>\n    -> <WorkerThread(WorkerThread2, started daemon 12060)>\n\n  File \"D:\\nikita\\tgbot\\venv\\lib\\site-packages\\telebot\\util.py\", line 69, in run\n    task(*args, **kwargs)\n    |     |       -> {}\n    |     -> (<telebot.types.Message object at 0x000002756ED95F08>,)\n    -> <function message_start.<locals>.handle_query.<locals>.contact at 0x000002756EDAE0D8>\n\n> File \"D:/nikita/tgbot/app.py\", line 67, in contact\n    if mailing.send_mail(data=data):\n       |       |              -> {'phone': '79161583883', 'user_name': '\u25c7\u0421\u0443\u0449', 'call': '\u0424\u043e\u0440\u043c\u0430 \u0438\u0437 \u0441\u0442\u0430\u0440\u0442\u043e\u0432\u043e\u0433\u043e \u043c\u0435\u043d\u044e'}\n       |       -> <function send_mail at 0x000002756ED1B318>\n       -> <module 'services.mailing' from 'D:\\\\nikita\\\\tgbot\\\\services\\\\mailing.py'>\n\n  File \"D:\\nikita\\tgbot\\services\\mailing.py\", line 50, in send_mail\n    server.login(sender_email, password)\n    |      |     |             -> 'N546823791'\n    |      |     -> 'belinsky.dev@gmail.com'\n    |      -> <function SMTP.login at 0x000002756EAD3168>\n    -> <smtplib.SMTP_SSL object at 0x000002756EDB3148>\n\n  File \"C:\\Users\\AV\\AppData\\Local\\Programs\\Python\\Python37\\lib\\smtplib.py\", line 730, in login\n    raise last_exception\n          -> SMTPAuthenticationError(535, b'5.7.8 Username and Password not accepted. Learn more at\\n5.7.8  https://support.google.com/mai...\n\n  File \"C:\\Users\\AV\\AppData\\Local\\Programs\\Python\\Python37\\lib\\smtplib.py\", line 721, in login\n    initial_response_ok=initial_response_ok)\n                        -> True\n\n  File \"C:\\Users\\AV\\AppData\\Local\\Programs\\Python\\Python37\\lib\\smtplib.py\", line 642, in auth\n    raise SMTPAuthenticationError(code, resp)\n          |                       |     -> b'5.7.8 Username and Password not accepted. Learn more at\\n5.7.8  https://support.google.com/mail/?p=BadCredentials v29sm3336...\n          |                       -> 535\n          -> <class 'smtplib.SMTPAuthenticationError'>\n\nsmtplib.SMTPAuthenticationError: (535, b'5.7.8 Username and Password not accepted. Learn more at\\n5.7.8  https://support.google.com/mail/?p=BadCredentials v29sm3336824lfq.230 - gsmtp')\n", "record": {"elapsed": {"repr": "0:00:17.241840", "seconds": 17.24184}, "exception": {"type": "SMTPAuthenticationError", "value": "(535, b'5.7.8 Username and Password not accepted. Learn more at\\n5.7.8  https://support.google.com/mail/?p=BadCredentials v29sm3336824lfq.230 - gsmtp')", "traceback": true}, "extra": {}, "file": {"name": "app.py", "path": "D:/nikita/tgbot/app.py"}, "function": "contact", "level": {"icon": "\u274c", "name": "ERROR", "no": 40}, "line": 67, "message": "An error has been caught in function 'contact', process 'MainProcess' (1976), thread 'WorkerThread2' (12060):", "module": "app", "name": "__main__", "process": {"id": 1976, "name": "MainProcess"}, "thread": {"id": 12060, "name": "WorkerThread2"}, "time": {"repr": "2021-02-02 16:13:48.414553+03:00", "timestamp": 1612271628.414553}}}
