{"text": "2021-02-02T15:34:56.477374+0300 ERROR An error has been caught in function 'contact', process 'MainProcess' (190270), thread 'WorkerThread1' (140295196534528):\nTraceback (most recent call last):\n\n  File \"/opt/python/python-3.7.6/lib/python3.7/threading.py\", line 890, in _bootstrap\n    self._bootstrap_inner()\n    \u2502    \u2514 <function Thread._bootstrap_inner at 0x7f990a2a59e0>\n    \u2514 <WorkerThread(WorkerThread1, started daemon 140295196534528)>\n  File \"/opt/python/python-3.7.6/lib/python3.7/threading.py\", line 926, in _bootstrap_inner\n    self.run()\n    \u2502    \u2514 <function WorkerThread.run at 0x7f99066ea440>\n    \u2514 <WorkerThread(WorkerThread1, started daemon 140295196534528)>\n  File \"/var/www/u0978519/data/pybot/lib/python3.7/site-packages/telebot/util.py\", line 69, in run\n    task(*args, **kwargs)\n    \u2502     \u2502       \u2514 {}\n    \u2502     \u2514 (<telebot.types.Message object at 0x7f99045354d0>,)\n    \u2514 <function message_start.<locals>.handle_query.<locals>.await_text.<locals>.contact at 0x7f99055c0dd0>\n\n> File \"app.py\", line 152, in contact\n    if mailing.send_mail(data=data, text=a):\n       \u2502       \u2502              \u2502          \u2514 '\u0445\u0430\u0447\u0443 \u0447\u0442\u043e\u0442\u043e \u043a\u043b\u0430\u0441\u0441\u043d\u043e\u0435'\n       \u2502       \u2502              \u2514 {'phone': '79161583883', 'user_name': '\u25c7\u0421\u0443\u0449', 'call': '\u041f\u043e\u0434 \u043a\u043b\u044e\u0447 -> \u041c\u043e\u0431\u0438\u043b\u044c\u043d\u043e\u0435 \u043f\u0440\u0438\u043b\u043e\u0436\u0435\u043d\u0438\u0435'}\n       \u2502       \u2514 <function send_mail at 0x7f990560d9e0>\n       \u2514 <module 'services.mailing' from '/var/www/u0978519/data/www/divier.space/telegramDivier/services/mailing.py'>\n\n  File \"/var/www/u0978519/data/www/divier.space/telegramDivier/services/mailing.py\", line 48, in send_mail\n    server.login(sender_email, password)\n    \u2502      \u2502     \u2502             \u2514 'N546823791n'\n    \u2502      \u2502     \u2514 'belinsky.dev@gmail.com'\n    \u2502      \u2514 <function SMTP.login at 0x7f9906438320>\n    \u2514 <smtplib.SMTP_SSL object at 0x7f99055bde50>\n\n  File \"/opt/python/python-3.7.6/lib/python3.7/smtplib.py\", line 730, in login\n    raise last_exception\n          \u2514 SMTPAuthenticationError(534, b'5.7.14 <https://accounts.google.com/signin/continue?sarp=1&scc=1&plt=AKgnsbs\\n5.7.14 1FF07PxDI...\n  File \"/opt/python/python-3.7.6/lib/python3.7/smtplib.py\", line 721, in login\n    initial_response_ok=initial_response_ok)\n                        \u2514 True\n  File \"/opt/python/python-3.7.6/lib/python3.7/smtplib.py\", line 642, in auth\n    raise SMTPAuthenticationError(code, resp)\n          \u2502                       \u2502     \u2514 b'5.7.14 <https://accounts.google.com/signin/continue?sarp=1&scc=1&plt=AKgnsbs\\n5.7.14 1FF07PxDI7AMFgHylIQWiYZmeZ2y4DLjEWPtgI...\n          \u2502                       \u2514 534\n          \u2514 <class 'smtplib.SMTPAuthenticationError'>\n\nsmtplib.SMTPAuthenticationError: (534, b'5.7.14 <https://accounts.google.com/signin/continue?sarp=1&scc=1&plt=AKgnsbs\\n5.7.14 1FF07PxDI7AMFgHylIQWiYZmeZ2y4DLjEWPtgIPRy9ttuwJWiduZzfyAO5EAzHCYQEikk\\n5.7.14 5ePHdQb75nUtxD-_FaCrWNz1GK0oUpKLl14EbUh369sEgggw_AZKl7y6Yf16nkIQ>\\n5.7.14 Please log in via your web browser and then try again.\\n5.7.14  Learn more at\\n5.7.14  https://support.google.com/mail/answer/78754 d23sm3302151lfn.229 - gsmtp')\n", "record": {"elapsed": {"repr": "0:00:35.331376", "seconds": 35.331376}, "exception": {"type": "SMTPAuthenticationError", "value": "(534, b'5.7.14 <https://accounts.google.com/signin/continue?sarp=1&scc=1&plt=AKgnsbs\\n5.7.14 1FF07PxDI7AMFgHylIQWiYZmeZ2y4DLjEWPtgIPRy9ttuwJWiduZzfyAO5EAzHCYQEikk\\n5.7.14 5ePHdQb75nUtxD-_FaCrWNz1GK0oUpKLl14EbUh369sEgggw_AZKl7y6Yf16nkIQ>\\n5.7.14 Please log in via your web browser and then try again.\\n5.7.14  Learn more at\\n5.7.14  https://support.google.com/mail/answer/78754 d23sm3302151lfn.229 - gsmtp')", "traceback": true}, "extra": {}, "file": {"name": "app.py", "path": "app.py"}, "function": "contact", "level": {"icon": "\u274c", "name": "ERROR", "no": 40}, "line": 152, "message": "An error has been caught in function 'contact', process 'MainProcess' (190270), thread 'WorkerThread1' (140295196534528):", "module": "app", "name": "__main__", "process": {"id": 190270, "name": "MainProcess"}, "thread": {"id": 140295196534528, "name": "WorkerThread1"}, "time": {"repr": "2021-02-02 15:34:56.477374+03:00", "timestamp": 1612269296.477374}}}
{"text": "2021-02-02T15:34:56.477374+0300 ERROR An error has been caught in function 'contact', process 'MainProcess' (190270), thread 'WorkerThread1' (140295196534528):\nTraceback (most recent call last):\n\n  File \"/opt/python/python-3.7.6/lib/python3.7/threading.py\", line 890, in _bootstrap\n    self._bootstrap_inner()\n    \u2502    \u2514 <function Thread._bootstrap_inner at 0x7f990a2a59e0>\n    \u2514 <WorkerThread(WorkerThread1, started daemon 140295196534528)>\n  File \"/opt/python/python-3.7.6/lib/python3.7/threading.py\", line 926, in _bootstrap_inner\n    self.run()\n    \u2502    \u2514 <function WorkerThread.run at 0x7f99066ea440>\n    \u2514 <WorkerThread(WorkerThread1, started daemon 140295196534528)>\n  File \"/var/www/u0978519/data/pybot/lib/python3.7/site-packages/telebot/util.py\", line 69, in run\n    task(*args, **kwargs)\n    \u2502     \u2502       \u2514 {}\n    \u2502     \u2514 (<telebot.types.Message object at 0x7f99045354d0>,)\n    \u2514 <function message_start.<locals>.handle_query.<locals>.await_text.<locals>.contact at 0x7f99055c0dd0>\n\n> File \"app.py\", line 152, in contact\n    if mailing.send_mail(data=data, text=a):\n       \u2502       \u2502              \u2502          \u2514 '\u0445\u0430\u0447\u0443 \u0447\u0442\u043e\u0442\u043e \u043a\u043b\u0430\u0441\u0441\u043d\u043e\u0435'\n       \u2502       \u2502              \u2514 {'phone': '79161583883', 'user_name': '\u25c7\u0421\u0443\u0449', 'call': '\u041f\u043e\u0434 \u043a\u043b\u044e\u0447 -> \u041c\u043e\u0431\u0438\u043b\u044c\u043d\u043e\u0435 \u043f\u0440\u0438\u043b\u043e\u0436\u0435\u043d\u0438\u0435'}\n       \u2502       \u2514 <function send_mail at 0x7f990560d9e0>\n       \u2514 <module 'services.mailing' from '/var/www/u0978519/data/www/divier.space/telegramDivier/services/mailing.py'>\n\n  File \"/var/www/u0978519/data/www/divier.space/telegramDivier/services/mailing.py\", line 48, in send_mail\n    server.login(sender_email, password)\n    \u2502      \u2502     \u2502             \u2514 'N546823791n'\n    \u2502      \u2502     \u2514 'belinsky.dev@gmail.com'\n    \u2502      \u2514 <function SMTP.login at 0x7f9906438320>\n    \u2514 <smtplib.SMTP_SSL object at 0x7f99055bde50>\n\n  File \"/opt/python/python-3.7.6/lib/python3.7/smtplib.py\", line 730, in login\n    raise last_exception\n          \u2514 SMTPAuthenticationError(534, b'5.7.14 <https://accounts.google.com/signin/continue?sarp=1&scc=1&plt=AKgnsbs\\n5.7.14 1FF07PxDI...\n  File \"/opt/python/python-3.7.6/lib/python3.7/smtplib.py\", line 721, in login\n    initial_response_ok=initial_response_ok)\n                        \u2514 True\n  File \"/opt/python/python-3.7.6/lib/python3.7/smtplib.py\", line 642, in auth\n    raise SMTPAuthenticationError(code, resp)\n          \u2502                       \u2502     \u2514 b'5.7.14 <https://accounts.google.com/signin/continue?sarp=1&scc=1&plt=AKgnsbs\\n5.7.14 1FF07PxDI7AMFgHylIQWiYZmeZ2y4DLjEWPtgI...\n          \u2502                       \u2514 534\n          \u2514 <class 'smtplib.SMTPAuthenticationError'>\n\nsmtplib.SMTPAuthenticationError: (534, b'5.7.14 <https://accounts.google.com/signin/continue?sarp=1&scc=1&plt=AKgnsbs\\n5.7.14 1FF07PxDI7AMFgHylIQWiYZmeZ2y4DLjEWPtgIPRy9ttuwJWiduZzfyAO5EAzHCYQEikk\\n5.7.14 5ePHdQb75nUtxD-_FaCrWNz1GK0oUpKLl14EbUh369sEgggw_AZKl7y6Yf16nkIQ>\\n5.7.14 Please log in via your web browser and then try again.\\n5.7.14  Learn more at\\n5.7.14  https://support.google.com/mail/answer/78754 d23sm3302151lfn.229 - gsmtp')\n", "record": {"elapsed": {"repr": "0:00:35.331376", "seconds": 35.331376}, "exception": {"type": "SMTPAuthenticationError", "value": "(534, b'5.7.14 <https://accounts.google.com/signin/continue?sarp=1&scc=1&plt=AKgnsbs\\n5.7.14 1FF07PxDI7AMFgHylIQWiYZmeZ2y4DLjEWPtgIPRy9ttuwJWiduZzfyAO5EAzHCYQEikk\\n5.7.14 5ePHdQb75nUtxD-_FaCrWNz1GK0oUpKLl14EbUh369sEgggw_AZKl7y6Yf16nkIQ>\\n5.7.14 Please log in via your web browser and then try again.\\n5.7.14  Learn more at\\n5.7.14  https://support.google.com/mail/answer/78754 d23sm3302151lfn.229 - gsmtp')", "traceback": true}, "extra": {}, "file": {"name": "app.py", "path": "app.py"}, "function": "contact", "level": {"icon": "\u274c", "name": "ERROR", "no": 40}, "line": 152, "message": "An error has been caught in function 'contact', process 'MainProcess' (190270), thread 'WorkerThread1' (140295196534528):", "module": "app", "name": "__main__", "process": {"id": 190270, "name": "MainProcess"}, "thread": {"id": 140295196534528, "name": "WorkerThread1"}, "time": {"repr": "2021-02-02 15:34:56.477374+03:00", "timestamp": 1612269296.477374}}}
{"text": "2021-02-02T15:48:05.424355+0300 ERROR An error has been caught in function 'contact', process 'MainProcess' (60012), thread 'WorkerThread1' (140325181925120):\nTraceback (most recent call last):\n\n  File \"/opt/python/python-3.7.6/lib/python3.7/threading.py\", line 890, in _bootstrap\n    self._bootstrap_inner()\n    \u2502    \u2514 <function Thread._bootstrap_inner at 0x7fa005695950>\n    \u2514 <WorkerThread(WorkerThread1, started daemon 140325181925120)>\n  File \"/opt/python/python-3.7.6/lib/python3.7/threading.py\", line 926, in _bootstrap_inner\n    self.run()\n    \u2502    \u2514 <function WorkerThread.run at 0x7fa001b410e0>\n    \u2514 <WorkerThread(WorkerThread1, started daemon 140325181925120)>\n  File \"/var/www/u0978519/data/pybot/lib/python3.7/site-packages/telebot/util.py\", line 69, in run\n    task(*args, **kwargs)\n    \u2502     \u2502       \u2514 {}\n    \u2502     \u2514 (<telebot.types.Message object at 0x7fa00018fe10>,)\n    \u2514 <function message_start.<locals>.handle_query.<locals>.contact at 0x7fa00018c170>\n\n> File \"app.py\", line 64, in contact\n    if mailing.send_mail(data=data):\n       \u2502       \u2502              \u2514 {'phone': '79161583883', 'user_name': '\u25c7\u0421\u0443\u0449', 'call': '\u0424\u043e\u0440\u043c\u0430 \u0438\u0437 \u0441\u0442\u0430\u0440\u0442\u043e\u0432\u043e\u0433\u043e \u043c\u0435\u043d\u044e'}\n       \u2502       \u2514 <function send_mail at 0x7fa000a68680>\n       \u2514 <module 'services.mailing' from '/var/www/u0978519/data/www/divier.space/telegramDivier/services/mailing.py'>\n\n  File \"/var/www/u0978519/data/www/divier.space/telegramDivier/services/mailing.py\", line 48, in send_mail\n    server.login(sender_email, password)\n    \u2502      \u2502     \u2502             \u2514 'N546823791n'\n    \u2502      \u2502     \u2514 'belinsky.dev@gmail.com'\n    \u2502      \u2514 <function SMTP.login at 0x7fa00188ef80>\n    \u2514 <smtplib.SMTP_SSL object at 0x7fa00560bf90>\n\n  File \"/opt/python/python-3.7.6/lib/python3.7/smtplib.py\", line 730, in login\n    raise last_exception\n          \u2514 SMTPAuthenticationError(534, b'5.7.14 <https://accounts.google.com/signin/continue?sarp=1&scc=1&plt=AKgnsbt\\n5.7.14 KvS9Xe2zS...\n  File \"/opt/python/python-3.7.6/lib/python3.7/smtplib.py\", line 721, in login\n    initial_response_ok=initial_response_ok)\n                        \u2514 True\n  File \"/opt/python/python-3.7.6/lib/python3.7/smtplib.py\", line 642, in auth\n    raise SMTPAuthenticationError(code, resp)\n          \u2502                       \u2502     \u2514 b'5.7.14 <https://accounts.google.com/signin/continue?sarp=1&scc=1&plt=AKgnsbt\\n5.7.14 KvS9Xe2zSYo44KvMT7ejyTZ2w_TViSc6p7J0OF...\n          \u2502                       \u2514 534\n          \u2514 <class 'smtplib.SMTPAuthenticationError'>\n\nsmtplib.SMTPAuthenticationError: (534, b'5.7.14 <https://accounts.google.com/signin/continue?sarp=1&scc=1&plt=AKgnsbt\\n5.7.14 KvS9Xe2zSYo44KvMT7ejyTZ2w_TViSc6p7J0OFhCeFMuBdB-cy6Gt_rcTajydgppMvLRv\\n5.7.14 nWfBAHydBoV6GlXLjeKmt1IeU-U-rrKRpA5AzkWzGF-qeYdCrwklqBOtu4nB-9x5>\\n5.7.14 Please log in via your web browser and then try again.\\n5.7.14  Learn more at\\n5.7.14  https://support.google.com/mail/answer/78754 c17sm3298265lfs.217 - gsmtp')\n", "record": {"elapsed": {"repr": "0:00:19.572905", "seconds": 19.572905}, "exception": {"type": "SMTPAuthenticationError", "value": "(534, b'5.7.14 <https://accounts.google.com/signin/continue?sarp=1&scc=1&plt=AKgnsbt\\n5.7.14 KvS9Xe2zSYo44KvMT7ejyTZ2w_TViSc6p7J0OFhCeFMuBdB-cy6Gt_rcTajydgppMvLRv\\n5.7.14 nWfBAHydBoV6GlXLjeKmt1IeU-U-rrKRpA5AzkWzGF-qeYdCrwklqBOtu4nB-9x5>\\n5.7.14 Please log in via your web browser and then try again.\\n5.7.14  Learn more at\\n5.7.14  https://support.google.com/mail/answer/78754 c17sm3298265lfs.217 - gsmtp')", "traceback": true}, "extra": {}, "file": {"name": "app.py", "path": "app.py"}, "function": "contact", "level": {"icon": "\u274c", "name": "ERROR", "no": 40}, "line": 64, "message": "An error has been caught in function 'contact', process 'MainProcess' (60012), thread 'WorkerThread1' (140325181925120):", "module": "app", "name": "__main__", "process": {"id": 60012, "name": "MainProcess"}, "thread": {"id": 140325181925120, "name": "WorkerThread1"}, "time": {"repr": "2021-02-02 15:48:05.424355+03:00", "timestamp": 1612270085.424355}}}
{"text": "2021-02-02T15:48:05.424355+0300 ERROR An error has been caught in function 'contact', process 'MainProcess' (60012), thread 'WorkerThread1' (140325181925120):\nTraceback (most recent call last):\n\n  File \"/opt/python/python-3.7.6/lib/python3.7/threading.py\", line 890, in _bootstrap\n    self._bootstrap_inner()\n    \u2502    \u2514 <function Thread._bootstrap_inner at 0x7fa005695950>\n    \u2514 <WorkerThread(WorkerThread1, started daemon 140325181925120)>\n  File \"/opt/python/python-3.7.6/lib/python3.7/threading.py\", line 926, in _bootstrap_inner\n    self.run()\n    \u2502    \u2514 <function WorkerThread.run at 0x7fa001b410e0>\n    \u2514 <WorkerThread(WorkerThread1, started daemon 140325181925120)>\n  File \"/var/www/u0978519/data/pybot/lib/python3.7/site-packages/telebot/util.py\", line 69, in run\n    task(*args, **kwargs)\n    \u2502     \u2502       \u2514 {}\n    \u2502     \u2514 (<telebot.types.Message object at 0x7fa00018fe10>,)\n    \u2514 <function message_start.<locals>.handle_query.<locals>.contact at 0x7fa00018c170>\n\n> File \"app.py\", line 64, in contact\n    if mailing.send_mail(data=data):\n       \u2502       \u2502              \u2514 {'phone': '79161583883', 'user_name': '\u25c7\u0421\u0443\u0449', 'call': '\u0424\u043e\u0440\u043c\u0430 \u0438\u0437 \u0441\u0442\u0430\u0440\u0442\u043e\u0432\u043e\u0433\u043e \u043c\u0435\u043d\u044e'}\n       \u2502       \u2514 <function send_mail at 0x7fa000a68680>\n       \u2514 <module 'services.mailing' from '/var/www/u0978519/data/www/divier.space/telegramDivier/services/mailing.py'>\n\n  File \"/var/www/u0978519/data/www/divier.space/telegramDivier/services/mailing.py\", line 48, in send_mail\n    server.login(sender_email, password)\n    \u2502      \u2502     \u2502             \u2514 'N546823791n'\n    \u2502      \u2502     \u2514 'belinsky.dev@gmail.com'\n    \u2502      \u2514 <function SMTP.login at 0x7fa00188ef80>\n    \u2514 <smtplib.SMTP_SSL object at 0x7fa00560bf90>\n\n  File \"/opt/python/python-3.7.6/lib/python3.7/smtplib.py\", line 730, in login\n    raise last_exception\n          \u2514 SMTPAuthenticationError(534, b'5.7.14 <https://accounts.google.com/signin/continue?sarp=1&scc=1&plt=AKgnsbt\\n5.7.14 KvS9Xe2zS...\n  File \"/opt/python/python-3.7.6/lib/python3.7/smtplib.py\", line 721, in login\n    initial_response_ok=initial_response_ok)\n                        \u2514 True\n  File \"/opt/python/python-3.7.6/lib/python3.7/smtplib.py\", line 642, in auth\n    raise SMTPAuthenticationError(code, resp)\n          \u2502                       \u2502     \u2514 b'5.7.14 <https://accounts.google.com/signin/continue?sarp=1&scc=1&plt=AKgnsbt\\n5.7.14 KvS9Xe2zSYo44KvMT7ejyTZ2w_TViSc6p7J0OF...\n          \u2502                       \u2514 534\n          \u2514 <class 'smtplib.SMTPAuthenticationError'>\n\nsmtplib.SMTPAuthenticationError: (534, b'5.7.14 <https://accounts.google.com/signin/continue?sarp=1&scc=1&plt=AKgnsbt\\n5.7.14 KvS9Xe2zSYo44KvMT7ejyTZ2w_TViSc6p7J0OFhCeFMuBdB-cy6Gt_rcTajydgppMvLRv\\n5.7.14 nWfBAHydBoV6GlXLjeKmt1IeU-U-rrKRpA5AzkWzGF-qeYdCrwklqBOtu4nB-9x5>\\n5.7.14 Please log in via your web browser and then try again.\\n5.7.14  Learn more at\\n5.7.14  https://support.google.com/mail/answer/78754 c17sm3298265lfs.217 - gsmtp')\n", "record": {"elapsed": {"repr": "0:00:19.572905", "seconds": 19.572905}, "exception": {"type": "SMTPAuthenticationError", "value": "(534, b'5.7.14 <https://accounts.google.com/signin/continue?sarp=1&scc=1&plt=AKgnsbt\\n5.7.14 KvS9Xe2zSYo44KvMT7ejyTZ2w_TViSc6p7J0OFhCeFMuBdB-cy6Gt_rcTajydgppMvLRv\\n5.7.14 nWfBAHydBoV6GlXLjeKmt1IeU-U-rrKRpA5AzkWzGF-qeYdCrwklqBOtu4nB-9x5>\\n5.7.14 Please log in via your web browser and then try again.\\n5.7.14  Learn more at\\n5.7.14  https://support.google.com/mail/answer/78754 c17sm3298265lfs.217 - gsmtp')", "traceback": true}, "extra": {}, "file": {"name": "app.py", "path": "app.py"}, "function": "contact", "level": {"icon": "\u274c", "name": "ERROR", "no": 40}, "line": 64, "message": "An error has been caught in function 'contact', process 'MainProcess' (60012), thread 'WorkerThread1' (140325181925120):", "module": "app", "name": "__main__", "process": {"id": 60012, "name": "MainProcess"}, "thread": {"id": 140325181925120, "name": "WorkerThread1"}, "time": {"repr": "2021-02-02 15:48:05.424355+03:00", "timestamp": 1612270085.424355}}}
{"text": "2021-02-02T15:50:09.040627+0300 ERROR An error has been caught in function 'contact', process 'MainProcess' (109336), thread 'WorkerThread2' (139813929658112):\nTraceback (most recent call last):\n\n  File \"/opt/python/python-3.7.6/lib/python3.7/threading.py\", line 890, in _bootstrap\n    self._bootstrap_inner()\n    \u2502    \u2514 <function Thread._bootstrap_inner at 0x7f28fceae950>\n    \u2514 <WorkerThread(WorkerThread2, started daemon 139813929658112)>\n  File \"/opt/python/python-3.7.6/lib/python3.7/threading.py\", line 926, in _bootstrap_inner\n    self.run()\n    \u2502    \u2514 <function WorkerThread.run at 0x7f28f931c0e0>\n    \u2514 <WorkerThread(WorkerThread2, started daemon 139813929658112)>\n  File \"/var/www/u0978519/data/pybot/lib/python3.7/site-packages/telebot/util.py\", line 69, in run\n    task(*args, **kwargs)\n    \u2502     \u2502       \u2514 {}\n    \u2502     \u2514 (<telebot.types.Message object at 0x7f28f6164410>,)\n    \u2514 <function message_start.<locals>.handle_query.<locals>.contact at 0x7f28f8242b00>\n\n> File \"app.py\", line 65, in contact\n    if mailing.send_mail(data=data):\n       \u2502       \u2502              \u2514 {'phone': '79161583883', 'user_name': '\u25c7\u0421\u0443\u0449', 'call': '\u0424\u043e\u0440\u043c\u0430 \u0438\u0437 \u0441\u0442\u0430\u0440\u0442\u043e\u0432\u043e\u0433\u043e \u043c\u0435\u043d\u044e'}\n       \u2502       \u2514 <function send_mail at 0x7f28f8242680>\n       \u2514 <module 'services.mailing' from '/var/www/u0978519/data/www/divier.space/telegramDivier/services/mailing.py'>\n\n  File \"/var/www/u0978519/data/www/divier.space/telegramDivier/services/mailing.py\", line 48, in send_mail\n    server.login(sender_email, password)\n    \u2502      \u2502     \u2502             \u2514 'N546823791n'\n    \u2502      \u2502     \u2514 'belinsky.dev@gmail.com'\n    \u2502      \u2514 <function SMTP.login at 0x7f28f9067f80>\n    \u2514 <smtplib.SMTP_SSL object at 0x7f28f616b910>\n\n  File \"/opt/python/python-3.7.6/lib/python3.7/smtplib.py\", line 730, in login\n    raise last_exception\n          \u2514 SMTPAuthenticationError(534, b'5.7.14 <https://accounts.google.com/signin/continue?sarp=1&scc=1&plt=AKgnsbt\\n5.7.14 a987VaSM1...\n  File \"/opt/python/python-3.7.6/lib/python3.7/smtplib.py\", line 721, in login\n    initial_response_ok=initial_response_ok)\n                        \u2514 True\n  File \"/opt/python/python-3.7.6/lib/python3.7/smtplib.py\", line 642, in auth\n    raise SMTPAuthenticationError(code, resp)\n          \u2502                       \u2502     \u2514 b'5.7.14 <https://accounts.google.com/signin/continue?sarp=1&scc=1&plt=AKgnsbt\\n5.7.14 a987VaSM1AiTfe0mBmLJPJqcMMnfKu2OYTck3N...\n          \u2502                       \u2514 534\n          \u2514 <class 'smtplib.SMTPAuthenticationError'>\n\nsmtplib.SMTPAuthenticationError: (534, b'5.7.14 <https://accounts.google.com/signin/continue?sarp=1&scc=1&plt=AKgnsbt\\n5.7.14 a987VaSM1AiTfe0mBmLJPJqcMMnfKu2OYTck3NwqQK6WM1P1LjjPvdgYqBS1dwk1UYe9w\\n5.7.14 M4DJVoc-CMe_y4bV3xmre6_4zCBZA7f1Xm8dCklRriyAiNlDXy2buqIgCBBZ5Vj4>\\n5.7.14 Please log in via your web browser and then try again.\\n5.7.14  Learn more at\\n5.7.14  https://support.google.com/mail/answer/78754 n7sm3296756lfu.123 - gsmtp')\n", "record": {"elapsed": {"repr": "0:00:12.002335", "seconds": 12.002335}, "exception": {"type": "SMTPAuthenticationError", "value": "(534, b'5.7.14 <https://accounts.google.com/signin/continue?sarp=1&scc=1&plt=AKgnsbt\\n5.7.14 a987VaSM1AiTfe0mBmLJPJqcMMnfKu2OYTck3NwqQK6WM1P1LjjPvdgYqBS1dwk1UYe9w\\n5.7.14 M4DJVoc-CMe_y4bV3xmre6_4zCBZA7f1Xm8dCklRriyAiNlDXy2buqIgCBBZ5Vj4>\\n5.7.14 Please log in via your web browser and then try again.\\n5.7.14  Learn more at\\n5.7.14  https://support.google.com/mail/answer/78754 n7sm3296756lfu.123 - gsmtp')", "traceback": true}, "extra": {}, "file": {"name": "app.py", "path": "app.py"}, "function": "contact", "level": {"icon": "\u274c", "name": "ERROR", "no": 40}, "line": 65, "message": "An error has been caught in function 'contact', process 'MainProcess' (109336), thread 'WorkerThread2' (139813929658112):", "module": "app", "name": "__main__", "process": {"id": 109336, "name": "MainProcess"}, "thread": {"id": 139813929658112, "name": "WorkerThread2"}, "time": {"repr": "2021-02-02 15:50:09.040627+03:00", "timestamp": 1612270209.040627}}}
{"text": "2021-02-02T15:50:09.040627+0300 ERROR An error has been caught in function 'contact', process 'MainProcess' (109336), thread 'WorkerThread2' (139813929658112):\nTraceback (most recent call last):\n\n  File \"/opt/python/python-3.7.6/lib/python3.7/threading.py\", line 890, in _bootstrap\n    self._bootstrap_inner()\n    \u2502    \u2514 <function Thread._bootstrap_inner at 0x7f28fceae950>\n    \u2514 <WorkerThread(WorkerThread2, started daemon 139813929658112)>\n  File \"/opt/python/python-3.7.6/lib/python3.7/threading.py\", line 926, in _bootstrap_inner\n    self.run()\n    \u2502    \u2514 <function WorkerThread.run at 0x7f28f931c0e0>\n    \u2514 <WorkerThread(WorkerThread2, started daemon 139813929658112)>\n  File \"/var/www/u0978519/data/pybot/lib/python3.7/site-packages/telebot/util.py\", line 69, in run\n    task(*args, **kwargs)\n    \u2502     \u2502       \u2514 {}\n    \u2502     \u2514 (<telebot.types.Message object at 0x7f28f6164410>,)\n    \u2514 <function message_start.<locals>.handle_query.<locals>.contact at 0x7f28f8242b00>\n\n> File \"app.py\", line 65, in contact\n    if mailing.send_mail(data=data):\n       \u2502       \u2502              \u2514 {'phone': '79161583883', 'user_name': '\u25c7\u0421\u0443\u0449', 'call': '\u0424\u043e\u0440\u043c\u0430 \u0438\u0437 \u0441\u0442\u0430\u0440\u0442\u043e\u0432\u043e\u0433\u043e \u043c\u0435\u043d\u044e'}\n       \u2502       \u2514 <function send_mail at 0x7f28f8242680>\n       \u2514 <module 'services.mailing' from '/var/www/u0978519/data/www/divier.space/telegramDivier/services/mailing.py'>\n\n  File \"/var/www/u0978519/data/www/divier.space/telegramDivier/services/mailing.py\", line 48, in send_mail\n    server.login(sender_email, password)\n    \u2502      \u2502     \u2502             \u2514 'N546823791n'\n    \u2502      \u2502     \u2514 'belinsky.dev@gmail.com'\n    \u2502      \u2514 <function SMTP.login at 0x7f28f9067f80>\n    \u2514 <smtplib.SMTP_SSL object at 0x7f28f616b910>\n\n  File \"/opt/python/python-3.7.6/lib/python3.7/smtplib.py\", line 730, in login\n    raise last_exception\n          \u2514 SMTPAuthenticationError(534, b'5.7.14 <https://accounts.google.com/signin/continue?sarp=1&scc=1&plt=AKgnsbt\\n5.7.14 a987VaSM1...\n  File \"/opt/python/python-3.7.6/lib/python3.7/smtplib.py\", line 721, in login\n    initial_response_ok=initial_response_ok)\n                        \u2514 True\n  File \"/opt/python/python-3.7.6/lib/python3.7/smtplib.py\", line 642, in auth\n    raise SMTPAuthenticationError(code, resp)\n          \u2502                       \u2502     \u2514 b'5.7.14 <https://accounts.google.com/signin/continue?sarp=1&scc=1&plt=AKgnsbt\\n5.7.14 a987VaSM1AiTfe0mBmLJPJqcMMnfKu2OYTck3N...\n          \u2502                       \u2514 534\n          \u2514 <class 'smtplib.SMTPAuthenticationError'>\n\nsmtplib.SMTPAuthenticationError: (534, b'5.7.14 <https://accounts.google.com/signin/continue?sarp=1&scc=1&plt=AKgnsbt\\n5.7.14 a987VaSM1AiTfe0mBmLJPJqcMMnfKu2OYTck3NwqQK6WM1P1LjjPvdgYqBS1dwk1UYe9w\\n5.7.14 M4DJVoc-CMe_y4bV3xmre6_4zCBZA7f1Xm8dCklRriyAiNlDXy2buqIgCBBZ5Vj4>\\n5.7.14 Please log in via your web browser and then try again.\\n5.7.14  Learn more at\\n5.7.14  https://support.google.com/mail/answer/78754 n7sm3296756lfu.123 - gsmtp')\n", "record": {"elapsed": {"repr": "0:00:12.002335", "seconds": 12.002335}, "exception": {"type": "SMTPAuthenticationError", "value": "(534, b'5.7.14 <https://accounts.google.com/signin/continue?sarp=1&scc=1&plt=AKgnsbt\\n5.7.14 a987VaSM1AiTfe0mBmLJPJqcMMnfKu2OYTck3NwqQK6WM1P1LjjPvdgYqBS1dwk1UYe9w\\n5.7.14 M4DJVoc-CMe_y4bV3xmre6_4zCBZA7f1Xm8dCklRriyAiNlDXy2buqIgCBBZ5Vj4>\\n5.7.14 Please log in via your web browser and then try again.\\n5.7.14  Learn more at\\n5.7.14  https://support.google.com/mail/answer/78754 n7sm3296756lfu.123 - gsmtp')", "traceback": true}, "extra": {}, "file": {"name": "app.py", "path": "app.py"}, "function": "contact", "level": {"icon": "\u274c", "name": "ERROR", "no": 40}, "line": 65, "message": "An error has been caught in function 'contact', process 'MainProcess' (109336), thread 'WorkerThread2' (139813929658112):", "module": "app", "name": "__main__", "process": {"id": 109336, "name": "MainProcess"}, "thread": {"id": 139813929658112, "name": "WorkerThread2"}, "time": {"repr": "2021-02-02 15:50:09.040627+03:00", "timestamp": 1612270209.040627}}}
